Workbook
Name SUBJECTS: '[1]INPUT DATA'!$A$1002:$A$1005

Sheet Instructions
D2: High School Class Record Template Instructions
D4: Data Input Tab
D6: 1. This tab contains three sections: Class Information, Subject Components, and Learner Information.
D8: 2. Complete the Class Information section and encode the corresponding weights for each assessment component under Subject Components.
D10: 3. Enter the learners' details in the Learner Information section.
D12: Assessment Input Tabs (Term 1, Term 2, and Term 3 Sheets)
D14: 1. These tabs are used to enter assessment scores for the applicable term(s). Depending on the subject offering, they may be used for Term 1 only, Terms 1 and 2, Term 3 only, or all three terms.
D16: 2. To enter scores for Written/Oral Works, Product/Performance Tasks, and Examinations, refer to the labels in the image below.
F18: STUDENT NAME | J18: 1 | K18: 2 | L18: 3
J19: 20 | K19: 20 | L19: 20 | N19: A
J20: 46201 | K20: 46202 | L20: 46203 | N20: B
J21: REC1 | K21: A1 | L21: Q1 | N21: C
F23: Santos, John Michael Reyes | J23: 18 | K23: 17 | L23: 4
F24: Cruz, Maria Angela Dela Peña | J24: 16 | K24: 12 | L24: 5
F25: Reyes, Joshua Miguel Ramos | J25: 14 | K25: 10 | L25: 10
F26: Garcia, Nicole Anne Villanueva | J26: 20 | K26: 8 | L26: 10
F28: A. Input the Highest Possible Score (HPS).
F29: B. Input the date.
F30: C. Personal Remarks – Any remarks may be entered here. Sample tags include:
F31: • A1 – Activity 1
F32: • REC1 – Recitation 1
F33: • Q1 – Quiz 1
F34: • 1L1 – 01 LMS Activity 1
F35: Other tags may be used as needed.
D37: 3. If an entered score exceeds the highest possible score, an error message will appear, as shown in the image below. Correct the score to ensure the accurate computation of grades for the corresponding assessment component.
F39: WRITTEN/ORAL WORKS
F40: 1 | G40: 2 | H40: 3 | I40: 4 | J40: 5 | K40: Total | L40: PS | M40: WS
F41: 20 | G41: 20 | H41: 20 | K41: 60 | L41: 100 | M41: 0.25
F42: 46201 | G42: 46202 | H42: 46203
F43: REC1 | G43: A1 | H43: Q1
F45: 18 | G45: 17 | H45: 4 | K45: 39 | L45: 65 | M45: 16.25
F46: 16 | G46: 12 | H46: 5 | K46: 33 | L46: 55 | M46: 13.75
F47: 14 | G47: 10 | H47: 10 | K47: 34 | L47: 56.666667 | M47: 14.166667
F48: 20 | G48: 8 | H48: 21 | K48: Error | L48: Error | M48: Error
D50: 4. The Status column beside the transmuted grade indicates whether the learner is At-Risk, Passed, or Failed, together with the corresponding qualitative descriptor [A, B, C, D, or E].
F52: Initial Grade | H52: Trasmuted Grade | J52: Status & Description
F54: 88 | H54: 90 | J54: Passed [A]
F55: 87 | H55: 89 | J55: Passed [B]
F56: 75.8 | H56: 79 | J56: Passed [C]
F57: 69 | H57: 74 | J57: Failed [D]
...

Sheet Descriptors Guide
C2: Qualitative Descriptors
D4: Numerical Grade | E4: Descriptor | F4: General Description | G4: Instructional Response
D6: 90 - 100 | E6: Advancing [A] (Namumukod-tangi) | F6: Consistently demonstrates skills and understanding that meet or exceed standards with independence, flexibility, and depth. | G6: Provide enrichment opportunities; encourage leadership, transfer, or peer mentoring.
D7: 80 - 89 | E7: Benchmarking [B] (Napamamalas) | F7: Demonstrates expected grade-level skills and understanding competently and idependently. | G7: Encourage deeper application, transfer of learning, and increased independence.
D8: 75 - 79 | E8: Connecting [C] (Natutungo) | F8: Demonstrates sufficient understanding and application of grade-level standards with occasional guidance and support. | G8: Provide guided practice to strengthen consistency, accuracy, and confidence.
D9: 65 - 74 | E9: Developing [D] (Napauunlad) | F9: Demonstrates partial understanding and inconsistent application of skills, requires targeted support and scaffolding. | G9: Provide targeted remediation, scaffolded instruction, and additional opportunities for practice.
D10: 0 - 64 | E10: Emerging [E] (Nagsisimula) | F10: Does not yet demonstrate foundational skills and understanding; requires intensive support. | G10: Implement structured and sustained intervention programs.

Sheet Data Input
C2: Data Input for High School Class Record
D4: CLASS INFORMATION | L4: LEARNER INFORMATION
D6: Campus | F6: : | G6: Naga | M6: STUDENT NO. | N6: STUDENT NAME
D7: Department | F7: : | G7: Senior High School (SHS) | L7: 1 | M7: 2000498439 | N7: ABENDANTE, CARL YUAN
D8: School Year | F8: : | G8: 2026 - 2027 | L8: 2 | M8: 2000483599 | N8: ACALA, AJI RHEYACELLE
L9: 3 | M9: 2000480423 | N9: BAER, SHANIA PEARL
D10: Instructor | F10: : | G10: John Marq E. Ramos | L10: 4 | M10: 2000487858 | N10: BAGAPORO, RYEANNA MHERYL
D11: Grade Level | F11: : | G11: 11 | L11: 5 | M11: 2000497598 | N11: BELARMINO, EASEAN
D12: Subject | F12: : | G12: General Mathematics | L12: 6 | M12: 2000504370 | N12: BORJA, GREEDY
L13: 7 | M13: 2000480420 | N13: CABALQUINTO, JUVY
D14: Code | F14: : | L14: 8 | M14: 2000487004 | N14: CONLU, MARC JEFFREY
L15: 9 | M15: 2000488434 | N15: DE LUNA, FELICITY RYNE
D16: Section | F16: : | G16: BE/ICT | L16: 10 | M16: 2000485973 | N16: DELOS REYES, GAVIN ZUE
D17: Room | F17: : | G17: 201 | L17: 11 | M17: 2000486374 | N17: DIANELA, MARY DIANE
D18: Schedule (Day) | F18: : | G18: Mon & Fri | L18: 12 | M18: 2000486376 | N18: DIKIT, JON JUIN
D19: Time | F19: : | G19: 09:00 to 10:30 AM | L19: 13 | M19: 2000490030 | N19: ESTOR, PHOEB REMEDIOS
L20: 14 | M20: 2000498660 | N20: ESTORIA, JOHN KYLE TIMOTHY
L21: 15 | M21: 2000485981 | N21: GARCIA, ARIORIE VEN AMHER
D22: SUBJECT COMPONENTS | L22: 16 | M22: 2000499229 | N22: GAVINO, REISHA LORRIANE
L23: 17 | M23: 2000481947 | N23: JACOBO, EZRA
L24: 18 | M24: 2000488472 | N24: JANI, JOSEPH LOUIE
D25: Written/Oral Works | H25: 0.2 | L25: 19 | M25: 2000494958 | N25: LEDESMA, CARL AUSTIN
D26: Product/Performance Tasks | H26: 0.5 | L26: 20 | M26: 2000498659 | N26: LLAMADO, JOHN JEROME
D27: Term Examination | H27: 0.3 | L27: 21 | M27: 2000496341 | N27: MAQUITE, JOHN MICHAEL
D28: Total | H28: =IF(COUNTA($H$25:$H$27)=0,"",IF(COUNT($H$25:$H$27)<>COUNTA($H$25:$H$27),"Error",SUM($H$25:$H$27))) -> 1 | L28: 22 | M28: 2000494490 | N28: MELGAR, NIZA JADE
L29: 23 | M29: 2000492883 | N29: MORADA, CARL ELY
L30: 24 | M30: 2000493062 | N30: OLORES, FRECIOUS NATALIE
L31: 25 | M31: 2000499699 | N31: ORTINERO, CHRISTEL ACE
L32: 26 | M32: 2000481841 | N32: PASCUA, JHON GAVRIEL
L33: 27 | M33: 2000492838 | N33: PASTOR, JAYDHEN
L34: 28 | M34: 2000485198 | N34: PLACENTE, RHIAN
L35: 29
L36: 30
L37: 31
L38: 32
L39: 33
L40: 34
L41: 35
L42: 36
L43: 37
...

Sheet Term 1
B2: =IF('Data Input'!$G$6="","",'Data Input'!$G$6) -> Naga | D2: =IF('Data Input'!$G$7="","",('Data Input'!$G$7)) -> Senior High School (SHS) | E2: =IF('Data Input'!$G$12="","",PROPER('Data Input'!$G$12)) -> General Mathematics | Y2: =IF('Data Input'!$G$14="","",UPPER('Data Input'!$G$14)) | AB2: =IF('Data Input'!$G$8="","",'Data Input'!$G$8) -> 2026 - 2027 | AE2: =IF(OR('Data Input'!$G$11="",'Data Input'!$G$16=""),"",UPPER('Data Input'!$G$11&" - "&'Data Input'!$G$16)) -> 11 - BE/ICT | AI2: =IF('Data Input'!$G$10="","",PROPER('Data Input'!$G$10)) -> John Marq E. Ramos | AR2: =IF('Data Input'!$G$17="","",'Data Input'!$G$17) -> 201 | AT2: =IF('Data Input'!$G$18="","",PROPER('Data Input'!$G$18)) -> Mon & Fri | AX2: =IF('Data Input'!$G$19="","",'Data Input'!$G$19) -> 09:00 to 10:30 AM | BB2: REMOVAL EXAM | BE2: SUMMARY
B3: Campus | D3: Department | E3: Subject | Y3: Code | AB3: School Year | AE3: Grade Level and Section | AI3: Instructor | AR3: Room | AT3: Schedule (Day) | AX3: Time
B4: TERM 1 | E4: WRITTEN/ORAL WORKS | AB4: PRODUCT/PERFORMANCE TASKS | AT4: EXAMINATION | BE4: Initial Grade | BF4: Transmuted Grade | BG4: Status & Description
B5: STUDENT NO. | D5: STUDENT NAME | E5: 1 | F5: 2 | G5: 3 | H5: 4 | I5: 5 | J5: 6 | K5: 7 | L5: 8 | M5: 9 | N5: 10 | O5: 11 | P5: 12 | Q5: 13 | R5: 14 | S5: 15 | T5: 16 | U5: 17 | V5: 18 | W5: 19 | X5: 20 | Y5: Total | Z5: PS | AA5: WS | AB5: 1 | AC5: 2 | AD5: 3 | AE5: 4 | AF5: 5 | AG5: 6 | AH5: 7 | AI5: 8 | AJ5: 9 | AK5: 10 | AL5: 11 | AM5: 12 | AN5: 13 | AO5: 14 | AP5: 15 | AQ5: Total | AR5: PS | AS5: WS | AT5: ST1 | AU5: ST2 | AV5: TE | AW5: WS ST1 | AX5: WS ST2 | AY5: WS TE | AZ5: PS (ST & TE) | BA5: WS (ST & TE) | BB5: RE | BC5: PS | BD5: Exam Remarks
E6: 20 | F6: 20 | G6: 10 | H6: 20 | Y6: =IF(COUNT($E6:$X6)=0,"",SUM($E6:$X6)) -> 70 | Z6: 100 | AA6: =IF(OR('Data Input'!$H$25="",'Data Input'!$H$25=0%),"--", IF('Data Input'!$H$28<>100%,"Error",'Data Input'!$H$25)) -> 0.2 | AB6: 50 | AC6: 100 | AQ6: =IF(COUNT($AB6:$AP6)=0,"",SUM($AB6:$AP6)) -> 150 | AR6: 100 | AS6: =IF(OR('Data Input'!$H$26="",'Data Input'!$H$26=0%),"--", IF('Data Input'!$H$28<>100%,"Error",'Data Input'!$H$26)) -> 0.5 | AT6: 45 | AU6: 45 | AV6: 100 | BB6: 100 | BC6: 100
AB7: 46242 | AC7: 46243 | AW7: 0.3 | AX7: 0.3 | AY7: 0.4 | AZ7: 100 | BA7: =IF(OR('Data Input'!$H$27="",'Data Input'!$H$27=0%),"--", IF('Data Input'!$H$28<>100%,"Error",'Data Input'!$H$27)) -> 0.3
E8: Q1 | F8: Q2 | G8: Q3 | H8: Q4 | AB8: PT1 | AC8: REC1 | AT8: 46247 | AU8: 46248 | AV8: 46249 | BB8: 46250
B9: 1 | C9: =IF('Data Input'!M7="","",'Data Input'!M7) -> 2000498439 | D9: =IF(ISBLANK('Data Input'!N7),"",PROPER('Data Input'!N7)) -> Abendante, Carl Yuan | E9: 9 | F9: 13 | G9: 6 | H9: 20 | Y9: {=_xlfn.LET( _xlpm.score,E9:X9, _xlpm.limit,$E$6:$X$6, IF(OR(D9="",COUNTA(_xlpm.score)=0),"", IF(COUNTA(_xlpm.score,_xlpm.limit)=0,"", IF( OR( SUM((_xlpm.limit="")*(_xlpm.score<>""))>0, SUM(ISTEXT(_xlpm.limit)*1)>0, SUM(ISTEXT(_xlpm.score)*1)>0, SUM(ISLOGICAL(_xlpm.limit)*1)>0, SUM(ISLOGICAL(_xlpm.score)*1)>0, SUM(ISERROR(_xlpm.limit)*1)>0, SUM(ISERROR(_xlpm.score)*1)>0 ), "Error", IF( SUM((ISNUMBER(_xlpm.limit)*ISNUMBER(_xlpm.score)*(_xlpm.score>_xlpm.limit))*1)>0, "Error", IF(SUM(_xlpm.score)>$Y$6, "Error", SUM(_xlpm.score) ))))))} -> 48 | Z9: =IF(D9="","",IF(Y9="Error","Error",IFERROR((Y9/$Y$6*$Z$6),""))) -> 68.571429 | AA9: =IFERROR(IF(D9="","",IF(Z9="Error","Error",(Z9*$AA$6))),"") -> 13.714286 | AB9: 45 | AC9: 90 | AQ9: {=_xlfn.LET( _xlpm.score,AB9:AP9, _xlpm.limit,$AB$6:$AP$6, IF(OR(D9="",COUNTA(_xlpm.score)=0),"", IF(COUNTA(_xlpm.score,_xlpm.limit)=0,"", IF( OR( SUM((_xlpm.limit="")*(_xlpm.score<>""))>0, SUM(ISTEXT(_xlpm.limit)*1)>0, SUM(ISTEXT(_xlpm.score)*1)>0, SUM(ISLOGICAL(_xlpm.limit)*1)>0, SUM(ISLOGICAL(_xlpm.score)*1)>0, SUM(ISERROR(_xlpm.limit)*1)>0, SUM(ISERROR(_xlpm.score)*1)>0 ), "Error", IF( SUM((ISNUMBER(_xlpm.limit)*ISNUMBER(_xlpm.score)*(_xlpm.score>_xlpm.limit))*1)>0, "Error", IF(SUM(_xlpm.score)>$AQ$6, "Error", SUM(_xlpm.score) ))))))} -> 135 | AR9: =IF(D9="","",IF(AQ9="Error","Error",IFERROR((AQ9/$AQ$6*$AR$6),""))) -> 90 | AS9: =IFERROR(IF(D9="","",IF(AR9="Error","Error",(AR9*$AS$6))),"") -> 45 | AT9: 39 | AU9: 32 | AV9: 79 | AW9: =IF(OR(D9="",AT9=""),"", IF($AT$6=0,"Error", IF(OR(AND($AT$6="",AT9<>""), ISTEXT($AT$6), ISTEXT(AT9), ISLOGICAL($AT$6), ISLOGICAL(AT9), ISERROR($AT$6), ISERROR(AT9)),"Error", IF(AT9>$AT$6,"Error", IF($AT$6=0,"",AT9/$AT$6*$AZ$7*$AW$7))))) -> 26 | AX9: =IF(OR(D9="",AU9=""),"", IF($AU$6=0,"Error", IF(OR(AND($AU$6="",AU9<>""), ISTEXT($AU$6), ISTEXT(AU9), ISLOGICAL($AU$6), ISLOGICAL(AU9), ISERROR($AU$6), ISERROR(AU9)),"Error", IF(AU9>$AU$6,"Error", IF($AU$6=0,"",AU9/$AU$6*$AZ$7*$AX$7))))) -> 21.333333 | AY9: =IF(OR(D9="",AV9=""),"", IF($AV$6=0,"Error", IF(OR(AND($AV$6="",AV9<>""), ISTEXT($AV$6), ISTEXT(AV9), ISLOGICAL($AV$6), ISLOGICAL(AV9), ISERROR($AV$6), ISERROR(AV9)),"Error", IF(AV9>$AV$6,"Error", IF($AV$6=0,"",AV9/$AV$6*$AZ$7*$AY$7))))) -> 31.6 | AZ9: =IF(D9="","",IF(COUNTIF(AW9:AY9,"Error")>0,"Error",IFERROR(IF(COUNT(AW9:AY9)=0,"",SUM(AW9:AY9)),""))) -> 78.933333 | BA9: =IFERROR(IF(D9="","",IF(AZ9="Error","Error",(AZ9*$BA$7))),"") -> 23.68 | BC9: =IF(OR(D9="",BB9=""),"",IF(BB9="Error","Error",IFERROR((BB9/$BB$6*$BC$6),""))) | BD9: =IF(AND(AY9="",BB9<>""),"Error",IF(BB9="","",IF(BB9>$BB$6,"Error",IF(BC9>=75,"Passed","Failed")))) | BE9: =_xlfn.LET( _xlpm.total,ROUND((N(AA9)+N(AS9)+N(BA9)),2), IF(OR(AA9="Error",AS9="Error",BA9="Error",BD9="Error"),"Error", IF(AND(AA9="",AS9="",BA9=""),"", IF(_xlpm.total>=70,_xlpm.total,IF(BD9="Passed",70,_xlpm.total))))) -> 82.39 | BF9: =IF(OR(AA9="Error",AS9="Error",BA9="Error",BD9="Error"),"Error", IF(D9="","", IF(AND(N($AA$6)+N($AS$6)+N($BA$7)=100%, OR(N($AA$6)=0,AA9<>""),OR(N($AS$6)=0,AS9<>""),OR(N($BA$7)=0,BA9<>""),BE9<>""), _xlfn.XLOOKUP(BE9,'Helper 1'!$B$3:$B$43,'Helper 1'!$D$3:$D$43,,-1),""))) -> 85 | BG9: {=_xlfn.LET( _xlpm.wWorks,$AA$6,_xlpm.pTask,$AS$6,_xlpm.examination,$BA$7, _xlpm.initialgrade,BE9,_xlpm.transmutedgrade,BF9,_xlpm.termExam,AY9, _xlpm.wWorkScore,AA9,_xlpm.pTaskScore,AS9,_xlpm.st1Score,AW9,_xlpm.st2Score,AX9,_xlpm.examScore,BA9,_xlpm.re,BD9, _xlpm.benchmark, _xlpm.wWorks*70*(_xlpm.wWorkScore<>"")+ _xlpm.pTask*70*(_xlpm.pTaskScore<>"")+ IF(_xlpm.wWorks+_xlpm.pTask<>100%, _xlpm.examination*21*((_xlpm.st1Score<>"")+(_xlpm.st2Score<>"")),0), _xlpm.remarks, _xlfn.IFS( N(_xlpm.transmutedgrade)>=90,"Passed [A]", N(_xlpm.transmutedgrade)>=80,"Passed [B]", N(_xlpm.transmutedgrade)>=75,"Passed [C]", N(_xlpm.transmutedgrade)>=65,"Failed [D]",TRUE,"Failed [E]"), IFERROR( IF(OR(_xlpm.wWorkScore="Error",_xlpm.pTaskScore="Error",_xlpm.examScore="Error",_xlpm.re="Error"),"Error", IF(_xlpm.transmutedgrade<>"", IF(_xlpm.wWorks+_xlpm.pTask=100%,_xlpm.remarks, IF(_xlpm.termExam="",IF(_xlpm.st2Score="", IF(_xlpm.initialgrade>=_xlpm.benchmark,"","At-Risk"), IF(N(_xlpm.transmutedgrade)<75,"At-Risk","")),_xlpm.remarks)), IF(_xlpm.initialgrade>=_xlpm.benchmark,"","At-Risk"))),""))} -> Passed [B]
B10: 2 | C10: =IF('Data Input'!M8="","",'Data Input'!M8) -> 2000483599 | D10: =IF(ISBLANK('Data Input'!N8),"",PROPER('Data Input'!N8)) -> Acala, Aji Rheyacelle | E10: 3 | F10: 9 | G10: 4 | H10: 20 | Y10: {=_xlfn.LET( _xlpm.score,E10:X10, _xlpm.limit,$E$6:$X$6, IF(OR(D10="",COUNTA(_xlpm.score)=0),"", IF(COUNTA(_xlpm.score,_xlpm.limit)=0,"", IF( OR( SUM((_xlpm.limit="")*(_xlpm.score<>""))>0, SUM(ISTEXT(_xlpm.limit)*1)>0, SUM(ISTEXT(_xlpm.score)*1)>0, SUM(ISLOGICAL(_xlpm.limit)*1)>0, SUM(ISLOGICAL(_xlpm.score)*1)>0, SUM(ISERROR(_xlpm.limit)*1)>0, SUM(ISERROR(_xlpm.score)*1)>0 ), "Error", IF( SUM((ISNUMBER(_xlpm.limit)*ISNUMBER(_xlpm.score)*(_xlpm.score>_xlpm.limit))*1)>0, "Error", IF(SUM(_xlpm.score)>$Y$6, "Error", SUM(_xlpm.score) ))))))} -> 36 | Z10: =IF(D10="","",IF(Y10="Error","Error",IFERROR((Y10/$Y$6*$Z$6),""))) -> 51.428571 | AA10: =IFERROR(IF(D10="","",IF(Z10="Error","Error",(Z10*$AA$6))),"") -> 10.285714 | AB10: 50 | AC10: 88 | AQ10: {=_xlfn.LET( _xlpm.score,AB10:AP10, _xlpm.limit,$AB$6:$AP$6, IF(OR(D10="",COUNTA(_xlpm.score)=0),"", IF(COUNTA(_xlpm.score,_xlpm.limit)=0,"", IF( OR( SUM((_xlpm.limit="")*(_xlpm.score<>""))>0, SUM(ISTEXT(_xlpm.limit)*1)>0, SUM(ISTEXT(_xlpm.score)*1)>0, SUM(ISLOGICAL(_xlpm.limit)*1)>0, SUM(ISLOGICAL(_xlpm.score)*1)>0, SUM(ISERROR(_xlpm.limit)*1)>0, SUM(ISERROR(_xlpm.score)*1)>0 ), "Error", IF( SUM((ISNUMBER(_xlpm.limit)*ISNUMBER(_xlpm.score)*(_xlpm.score>_xlpm.limit))*1)>0, "Error", IF(SUM(_xlpm.score)>$AQ$6, "Error", SUM(_xlpm.score) ))))))} -> 138 | AR10: =IF(D10="","",IF(AQ10="Error","Error",IFERROR((AQ10/$AQ$6*$AR$6),""))) -> 92 | AS10: =IFERROR(IF(D10="","",IF(AR10="Error","Error",(AR10*$AS$6))),"") -> 46 | AT10: 35 | AU10: 38 | AV10: 65 | AW10: =IF(OR(D10="",AT10=""),"", IF($AT$6=0,"Error", IF(OR(AND($AT$6="",AT10<>""), ISTEXT($AT$6), ISTEXT(AT10), ISLOGICAL($AT$6), ISLOGICAL(AT10), ISERROR($AT$6), ISERROR(AT10)),"Error", IF(AT10>$AT$6,"Error", IF($AT$6=0,"",AT10/$AT$6*$AZ$7*$AW$7))))) -> 23.333333 | AX10: =IF(OR(D10="",AU10=""),"", IF($AU$6=0,"Error", IF(OR(AND($AU$6="",AU10<>""), ISTEXT($AU$6), ISTEXT(AU10), ISLOGICAL($AU$6), ISLOGICAL(AU10), ISERROR($AU$6), ISERROR(AU10)),"Error", IF(AU10>$AU$6,"Error", IF($AU$6=0,"",AU10/$AU$6*$AZ$7*$AX$7))))) -> 25.333333 | AY10: =IF(OR(D10="",AV10=""),"", IF($AV$6=0,"Error", IF(OR(AND($AV$6="",AV10<>""), ISTEXT($AV$6), ISTEXT(AV10), ISLOGICAL($AV$6), ISLOGICAL(AV10), ISERROR($AV$6), ISERROR(AV10)),"Error", IF(AV10>$AV$6,"Error", IF($AV$6=0,"",AV10/$AV$6*$AZ$7*$AY$7))))) -> 26 | AZ10: =IF(D10="","",IF(COUNTIF(AW10:AY10,"Error")>0,"Error",IFERROR(IF(COUNT(AW10:AY10)=0,"",SUM(AW10:AY10)),""))) -> 74.666667 | BA10: =IFERROR(IF(D10="","",IF(AZ10="Error","Error",(AZ10*$BA$7))),"") -> 22.4 | BC10: =IF(OR(D10="",BB10=""),"",IF(BB10="Error","Error",IFERROR((BB10/$BB$6*$BC$6),""))) | BD10: =IF(AND(AY10="",BB10<>""),"Error",IF(BB10="","",IF(BB10>$BB$6,"Error",IF(BC10>=75,"Passed","Failed")))) | BE10: =_xlfn.LET( _xlpm.total,ROUND((N(AA10)+N(AS10)+N(BA10)),2), IF(OR(AA10="Error",AS10="Error",BA10="Error",BD10="Error"),"Error", IF(AND(AA10="",AS10="",BA10=""),"", IF(_xlpm.total>=70,_xlpm.total,IF(BD10="Passed",70,_xlpm.total))))) -> 78.69 | BF10: =IF(OR(AA10="Error",AS10="Error",BA10="Error",BD10="Error"),"Error", IF(D10="","", IF(AND(N($AA$6)+N($AS$6)+N($BA$7)=100%, OR(N($AA$6)=0,AA10<>""),OR(N($AS$6)=0,AS10<>""),OR(N($BA$7)=0,BA10<>""),BE10<>""), _xlfn.XLOOKUP(BE10,'Helper 1'!$B$3:$B$43,'Helper 1'!$D$3:$D$43,,-1),""))) -> 82 | BG10: {=_xlfn.LET( _xlpm.wWorks,$AA$6,_xlpm.pTask,$AS$6,_xlpm.examination,$BA$7, _xlpm.initialgrade,BE10,_xlpm.transmutedgrade,BF10,_xlpm.termExam,AY10, _xlpm.wWorkScore,AA10,_xlpm.pTaskScore,AS10,_xlpm.st1Score,AW10,_xlpm.st2Score,AX10,_xlpm.examScore,BA10,_xlpm.re,BD10, _xlpm.benchmark, _xlpm.wWorks*70*(_xlpm.wWorkScore<>"")+ _xlpm.pTask*70*(_xlpm.pTaskScore<>"")+ IF(_xlpm.wWorks+_xlpm.pTask<>100%, _xlpm.examination*21*((_xlpm.st1Score<>"")+(_xlpm.st2Score<>"")),0), _xlpm.remarks, _xlfn.IFS( N(_xlpm.transmutedgrade)>=90,"Passed [A]", N(_xlpm.transmutedgrade)>=80,"Passed [B]", N(_xlpm.transmutedgrade)>=75,"Passed [C]", N(_xlpm.transmutedgrade)>=65,"Failed [D]",TRUE,"Failed [E]"), IFERROR( IF(OR(_xlpm.wWorkScore="Error",_xlpm.pTaskScore="Error",_xlpm.examScore="Error",_xlpm.re="Error"),"Error", IF(_xlpm.transmutedgrade<>"", IF(_xlpm.wWorks+_xlpm.pTask=100%,_xlpm.remarks, IF(_xlpm.termExam="",IF(_xlpm.st2Score="", IF(_xlpm.initialgrade>=_xlpm.benchmark,"","At-Risk"), IF(N(_xlpm.transmutedgrade)<75,"At-Risk","")),_xlpm.remarks)), IF(_xlpm.initialgrade>=_xlpm.benchmark,"","At-Risk"))),""))} -> Passed [B]
B11: 3 | C11: =IF('Data Input'!M9="","",'Data Input'!M9) -> 2000480423 | D11: =IF(ISBLANK('Data Input'!N9),"",PROPER('Data Input'!N9)) -> Baer, Shania Pearl | E11: 14 | F11: 12 | G11: 7 | H11: 20 | Y11: {=_xlfn.LET( _xlpm.score,E11:X11, _xlpm.limit,$E$6:$X$6, IF(OR(D11="",COUNTA(_xlpm.score)=0),"", IF(COUNTA(_xlpm.score,_xlpm.limit)=0,"", IF( OR( SUM((_xlpm.limit="")*(_xlpm.score<>""))>0, SUM(ISTEXT(_xlpm.limit)*1)>0, SUM(ISTEXT(_xlpm.score)*1)>0, SUM(ISLOGICAL(_xlpm.limit)*1)>0, SUM(ISLOGICAL(_xlpm.score)*1)>0, SUM(ISERROR(_xlpm.limit)*1)>0, SUM(ISERROR(_xlpm.score)*1)>0 ), "Error", IF( SUM((ISNUMBER(_xlpm.limit)*ISNUMBER(_xlpm.score)*(_xlpm.score>_xlpm.limit))*1)>0, "Error", IF(SUM(_xlpm.score)>$Y$6, "Error", SUM(_xlpm.score) ))))))} -> 53 | Z11: =IF(D11="","",IF(Y11="Error","Error",IFERROR((Y11/$Y$6*$Z$6),""))) -> 75.714286 | AA11: =IFERROR(IF(D11="","",IF(Z11="Error","Error",(Z11*$AA$6))),"") -> 15.142857 | AB11: 50 | AC11: 88 | AQ11: {=_xlfn.LET( _xlpm.score,AB11:AP11, _xlpm.limit,$AB$6:$AP$6, IF(OR(D11="",COUNTA(_xlpm.score)=0),"", IF(COUNTA(_xlpm.score,_xlpm.limit)=0,"", IF( OR( SUM((_xlpm.limit="")*(_xlpm.score<>""))>0, SUM(ISTEXT(_xlpm.limit)*1)>0, SUM(ISTEXT(_xlpm.score)*1)>0, SUM(ISLOGICAL(_xlpm.limit)*1)>0, SUM(ISLOGICAL(_xlpm.score)*1)>0, SUM(ISERROR(_xlpm.limit)*1)>0, SUM(ISERROR(_xlpm.score)*1)>0 ), "Error", IF( SUM((ISNUMBER(_xlpm.limit)*ISNUMBER(_xlpm.score)*(_xlpm.score>_xlpm.limit))*1)>0, "Error", IF(SUM(_xlpm.score)>$AQ$6, "Error", SUM(_xlpm.score) ))))))} -> 138 | AR11: =IF(D11="","",IF(AQ11="Error","Error",IFERROR((AQ11/$AQ$6*$AR$6),""))) -> 92 | AS11: =IFERROR(IF(D11="","",IF(AR11="Error","Error",(AR11*$AS$6))),"") -> 46 | AT11: 38 | AU11: 37 | AV11: 50 | AW11: =IF(OR(D11="",AT11=""),"", IF($AT$6=0,"Error", IF(OR(AND($AT$6="",AT11<>""), ISTEXT($AT$6), ISTEXT(AT11), ISLOGICAL($AT$6), ISLOGICAL(AT11), ISERROR($AT$6), ISERROR(AT11)),"Error", IF(AT11>$AT$6,"Error", IF($AT$6=0,"",AT11/$AT$6*$AZ$7*$AW$7))))) -> 25.333333 | AX11: =IF(OR(D11="",AU11=""),"", IF($AU$6=0,"Error", IF(OR(AND($AU$6="",AU11<>""), ISTEXT($AU$6), ISTEXT(AU11), ISLOGICAL($AU$6), ISLOGICAL(AU11), ISERROR($AU$6), ISERROR(AU11)),"Error", IF(AU11>$AU$6,"Error", IF($AU$6=0,"",AU11/$AU$6*$AZ$7*$AX$7))))) -> 24.666667 | AY11: =IF(OR(D11="",AV11=""),"", IF($AV$6=0,"Error", IF(OR(AND($AV$6="",AV11<>""), ISTEXT($AV$6), ISTEXT(AV11), ISLOGICAL($AV$6), ISLOGICAL(AV11), ISERROR($AV$6), ISERROR(AV11)),"Error", IF(AV11>$AV$6,"Error", IF($AV$6=0,"",AV11/$AV$6*$AZ$7*$AY$7))))) -> 20 | AZ11: =IF(D11="","",IF(COUNTIF(AW11:AY11,"Error")>0,"Error",IFERROR(IF(COUNT(AW11:AY11)=0,"",SUM(AW11:AY11)),""))) -> 70 | BA11: =IFERROR(IF(D11="","",IF(AZ11="Error","Error",(AZ11*$BA$7))),"") -> 21 | BC11: =IF(OR(D11="",BB11=""),"",IF(BB11="Error","Error",IFERROR((BB11/$BB$6*$BC$6),""))) | BD11: =IF(AND(AY11="",BB11<>""),"Error",IF(BB11="","",IF(BB11>$BB$6,"Error",IF(BC11>=75,"Passed","Failed")))) | BE11: =_xlfn.LET( _xlpm.total,ROUND((N(AA11)+N(AS11)+N(BA11)),2), IF(OR(AA11="Error",AS11="Error",BA11="Error",BD11="Error"),"Error", IF(AND(AA11="",AS11="",BA11=""),"", IF(_xlpm.total>=70,_xlpm.total,IF(BD11="Passed",70,_xlpm.total))))) -> 82.14 | BF11: =IF(OR(AA11="Error",AS11="Error",BA11="Error",BD11="Error"),"Error", IF(D11="","", IF(AND(N($AA$6)+N($AS$6)+N($BA$7)=100%, OR(N($AA$6)=0,AA11<>""),OR(N($AS$6)=0,AS11<>""),OR(N($BA$7)=0,BA11<>""),BE11<>""), _xlfn.XLOOKUP(BE11,'Helper 1'!$B$3:$B$43,'Helper 1'!$D$3:$D$43,,-1),""))) -> 85 | BG11: {=_xlfn.LET( _xlpm.wWorks,$AA$6,_xlpm.pTask,$AS$6,_xlpm.examination,$BA$7, _xlpm.initialgrade,BE11,_xlpm.transmutedgrade,BF11,_xlpm.termExam,AY11, _xlpm.wWorkScore,AA11,_xlpm.pTaskScore,AS11,_xlpm.st1Score,AW11,_xlpm.st2Score,AX11,_xlpm.examScore,BA11,_xlpm.re,BD11, _xlpm.benchmark, _xlpm.wWorks*70*(_xlpm.wWorkScore<>"")+ _xlpm.pTask*70*(_xlpm.pTaskScore<>"")+ IF(_xlpm.wWorks+_xlpm.pTask<>100%, _xlpm.examination*21*((_xlpm.st1Score<>"")+(_xlpm.st2Score<>"")),0), _xlpm.remarks, _xlfn.IFS( N(_xlpm.transmutedgrade)>=90,"Passed [A]", N(_xlpm.transmutedgrade)>=80,"Passed [B]", N(_xlpm.transmutedgrade)>=75,"Passed [C]", N(_xlpm.transmutedgrade)>=65,"Failed [D]",TRUE,"Failed [E]"), IFERROR( IF(OR(_xlpm.wWorkScore="Error",_xlpm.pTaskScore="Error",_xlpm.examScore="Error",_xlpm.re="Error"),"Error", IF(_xlpm.transmutedgrade<>"", IF(_xlpm.wWorks+_xlpm.pTask=100%,_xlpm.remarks, IF(_xlpm.termExam="",IF(_xlpm.st2Score="", IF(_xlpm.initialgrade>=_xlpm.benchmark,"","At-Risk"), IF(N(_xlpm.transmutedgrade)<75,"At-Risk","")),_xlpm.remarks)), IF(_xlpm.initialgrade>=_xlpm.benchmark,"","At-Risk"))),""))} -> Passed [B]
B12: 4 | C12: =IF('Data Input'!M10="","",'Data Input'!M10) -> 2000487858 | D12: =IF(ISBLANK('Data Input'!N10),"",PROPER('Data Input'!N10)) -> Bagaporo, Ryeanna Mheryl | E12: 1 | F12: 11 | G12: 3 | H12: 20 | Y12: {=_xlfn.LET( _xlpm.score,E12:X12, _xlpm.limit,$E$6:$X$6, IF(OR(D12="",COUNTA(_xlpm.score)=0),"", IF(COUNTA(_xlpm.score,_xlpm.limit)=0,"", IF( OR( SUM((_xlpm.limit="")*(_xlpm.score<>""))>0, SUM(ISTEXT(_xlpm.limit)*1)>0, SUM(ISTEXT(_xlpm.score)*1)>0, SUM(ISLOGICAL(_xlpm.limit)*1)>0, SUM(ISLOGICAL(_xlpm.score)*1)>0, SUM(ISERROR(_xlpm.limit)*1)>0, SUM(ISERROR(_xlpm.score)*1)>0 ), "Error", IF( SUM((ISNUMBER(_xlpm.limit)*ISNUMBER(_xlpm.score)*(_xlpm.score>_xlpm.limit))*1)>0, "Error", IF(SUM(_xlpm.score)>$Y$6, "Error", SUM(_xlpm.score) ))))))} -> 35 | Z12: =IF(D12="","",IF(Y12="Error","Error",IFERROR((Y12/$Y$6*$Z$6),""))) -> 50 | AA12: =IFERROR(IF(D12="","",IF(Z12="Error","Error",(Z12*$AA$6))),"") -> 10 | AB12: 47 | AC12: 88 | AQ12: {=_xlfn.LET( _xlpm.score,AB12:AP12, _xlpm.limit,$AB$6:$AP$6, IF(OR(D12="",COUNTA(_xlpm.score)=0),"", IF(COUNTA(_xlpm.score,_xlpm.limit)=0,"", IF( OR( SUM((_xlpm.limit="")*(_xlpm.score<>""))>0, SUM(ISTEXT(_xlpm.limit)*1)>0, SUM(ISTEXT(_xlpm.score)*1)>0, SUM(ISLOGICAL(_xlpm.limit)*1)>0, SUM(ISLOGICAL(_xlpm.score)*1)>0, SUM(ISERROR(_xlpm.limit)*1)>0, SUM(ISERROR(_xlpm.score)*1)>0 ), "Error", IF( SUM((ISNUMBER(_xlpm.limit)*ISNUMBER(_xlpm.score)*(_xlpm.score>_xlpm.limit))*1)>0, "Error", IF(SUM(_xlpm.score)>$AQ$6, "Error", SUM(_xlpm.score) ))))))} -> 135 | AR12: =IF(D12="","",IF(AQ12="Error","Error",IFERROR((AQ12/$AQ$6*$AR$6),""))) -> 90 | AS12: =IFERROR(IF(D12="","",IF(AR12="Error","Error",(AR12*$AS$6))),"") -> 45 | AT12: 26 | AU12: 31 | AV12: 37 | AW12: =IF(OR(D12="",AT12=""),"", IF($AT$6=0,"Error", IF(OR(AND($AT$6="",AT12<>""), ISTEXT($AT$6), ISTEXT(AT12), ISLOGICAL($AT$6), ISLOGICAL(AT12), ISERROR($AT$6), ISERROR(AT12)),"Error", IF(AT12>$AT$6,"Error", IF($AT$6=0,"",AT12/$AT$6*$AZ$7*$AW$7))))) -> 17.333333 | AX12: =IF(OR(D12="",AU12=""),"", IF($AU$6=0,"Error", IF(OR(AND($AU$6="",AU12<>""), ISTEXT($AU$6), ISTEXT(AU12), ISLOGICAL($AU$6), ISLOGICAL(AU12), ISERROR($AU$6), ISERROR(AU12)),"Error", IF(AU12>$AU$6,"Error", IF($AU$6=0,"",AU12/$AU$6*$AZ$7*$AX$7))))) -> 20.666667 | AY12: =IF(OR(D12="",AV12=""),"", IF($AV$6=0,"Error", IF(OR(AND($AV$6="",AV12<>""), ISTEXT($AV$6), ISTEXT(AV12), ISLOGICAL($AV$6), ISLOGICAL(AV12), ISERROR($AV$6), ISERROR(AV12)),"Error", IF(AV12>$AV$6,"Error", IF($AV$6=0,"",AV12/$AV$6*$AZ$7*$AY$7))))) -> 14.8 | AZ12: =IF(D12="","",IF(COUNTIF(AW12:AY12,"Error")>0,"Error",IFERROR(IF(COUNT(AW12:AY12)=0,"",SUM(AW12:AY12)),""))) -> 52.8 | BA12: =IFERROR(IF(D12="","",IF(AZ12="Error","Error",(AZ12*$BA$7))),"") -> 15.84 | BC12: =IF(OR(D12="",BB12=""),"",IF(BB12="Error","Error",IFERROR((BB12/$BB$6*$BC$6),""))) | BD12: =IF(AND(AY12="",BB12<>""),"Error",IF(BB12="","",IF(BB12>$BB$6,"Error",IF(BC12>=75,"Passed","Failed")))) | BE12: =_xlfn.LET( _xlpm.total,ROUND((N(AA12)+N(AS12)+N(BA12)),2), IF(OR(AA12="Error",AS12="Error",BA12="Error",BD12="Error"),"Error", IF(AND(AA12="",AS12="",BA12=""),"", IF(_xlpm.total>=70,_xlpm.total,IF(BD12="Passed",70,_xlpm.total))))) -> 70.84 | BF12: =IF(OR(AA12="Error",AS12="Error",BA12="Error",BD12="Error"),"Error", IF(D12="","", IF(AND(N($AA$6)+N($AS$6)+N($BA$7)=100%, OR(N($AA$6)=0,AA12<>""),OR(N($AS$6)=0,AS12<>""),OR(N($BA$7)=0,BA12<>""),BE12<>""), _xlfn.XLOOKUP(BE12,'Helper 1'!$B$3:$B$43,'Helper 1'!$D$3:$D$43,,-1),""))) -> 75 | BG12: {=_xlfn.LET( _xlpm.wWorks,$AA$6,_xlpm.pTask,$AS$6,_xlpm.examination,$BA$7, _xlpm.initialgrade,BE12,_xlpm.transmutedgrade,BF12,_xlpm.termExam,AY12, _xlpm.wWorkScore,AA12,_xlpm.pTaskScore,AS12,_xlpm.st1Score,AW12,_xlpm.st2Score,AX12,_xlpm.examScore,BA12,_xlpm.re,BD12, _xlpm.benchmark, _xlpm.wWorks*70*(_xlpm.wWorkScore<>"")+ _xlpm.pTask*70*(_xlpm.pTaskScore<>"")+ IF(_xlpm.wWorks+_xlpm.pTask<>100%, _xlpm.examination*21*((_xlpm.st1Score<>"")+(_xlpm.st2Score<>"")),0), _xlpm.remarks, _xlfn.IFS( N(_xlpm.transmutedgrade)>=90,"Passed [A]", N(_xlpm.transmutedgrade)>=80,"Passed [B]", N(_xlpm.transmutedgrade)>=75,"Passed [C]", N(_xlpm.transmutedgrade)>=65,"Failed [D]",TRUE,"Failed [E]"), IFERROR( IF(OR(_xlpm.wWorkScore="Error",_xlpm.pTaskScore="Error",_xlpm.examScore="Error",_xlpm.re="Error"),"Error", IF(_xlpm.transmutedgrade<>"", IF(_xlpm.wWorks+_xlpm.pTask=100%,_xlpm.remarks, IF(_xlpm.termExam="",IF(_xlpm.st2Score="", IF(_xlpm.initialgrade>=_xlpm.benchmark,"","At-Risk"), IF(N(_xlpm.transmutedgrade)<75,"At-Risk","")),_xlpm.remarks)), IF(_xlpm.initialgrade>=_xlpm.benchmark,"","At-Risk"))),""))} -> Passed [C]
B13: 5 | C13: =IF('Data Input'!M11="","",'Data Input'!M11) -> 2000497598 | D13: =IF(ISBLANK('Data Input'!N11),"",PROPER('Data Input'!N11)) -> Belarmino, Easean | E13: 2 | F13: 10 | G13: 5 | H13: 20 | Y13: {=_xlfn.LET( _xlpm.score,E13:X13, _xlpm.limit,$E$6:$X$6, IF(OR(D13="",COUNTA(_xlpm.score)=0),"", IF(COUNTA(_xlpm.score,_xlpm.limit)=0,"", IF( OR( SUM((_xlpm.limit="")*(_xlpm.score<>""))>0, SUM(ISTEXT(_xlpm.limit)*1)>0, SUM(ISTEXT(_xlpm.score)*1)>0, SUM(ISLOGICAL(_xlpm.limit)*1)>0, SUM(ISLOGICAL(_xlpm.score)*1)>0, SUM(ISERROR(_xlpm.limit)*1)>0, SUM(ISERROR(_xlpm.score)*1)>0 ), "Error", IF( SUM((ISNUMBER(_xlpm.limit)*ISNUMBER(_xlpm.score)*(_xlpm.score>_xlpm.limit))*1)>0, "Error", IF(SUM(_xlpm.score)>$Y$6, "Error", SUM(_xlpm.score) ))))))} -> 37 | Z13: =IF(D13="","",IF(Y13="Error","Error",IFERROR((Y13/$Y$6*$Z$6),""))) -> 52.857143 | AA13: =IFERROR(IF(D13="","",IF(Z13="Error","Error",(Z13*$AA$6))),"") -> 10.571429 | AB13: 50 | AC13: 92 | AQ13: {=_xlfn.LET( _xlpm.score,AB13:AP13, _xlpm.limit,$AB$6:$AP$6, IF(OR(D13="",COUNTA(_xlpm.score)=0),"", IF(COUNTA(_xlpm.score,_xlpm.limit)=0,"", IF( OR( SUM((_xlpm.limit="")*(_xlpm.score<>""))>0, SUM(ISTEXT(_xlpm.limit)*1)>0, SUM(ISTEXT(_xlpm.score)*1)>0, SUM(ISLOGICAL(_xlpm.limit)*1)>0, SUM(ISLOGICAL(_xlpm.score)*1)>0, SUM(ISERROR(_xlpm.limit)*1)>0, SUM(ISERROR(_xlpm.score)*1)>0 ), "Error", IF( SUM((ISNUMBER(_xlpm.limit)*ISNUMBER(_xlpm.score)*(_xlpm.score>_xlpm.limit))*1)>0, "Error", IF(SUM(_xlpm.score)>$AQ$6, "Error", SUM(_xlpm.score) ))))))} -> 142 | AR13: =IF(D13="","",IF(AQ13="Error","Error",IFERROR((AQ13/$AQ$6*$AR$6),""))) -> 94.666667 | AS13: =IFERROR(IF(D13="","",IF(AR13="Error","Error",(AR13*$AS$6))),"") -> 47.333333 | AT13: 43 | AU13: 37 | AW13: =IF(OR(D13="",AT13=""),"", IF($AT$6=0,"Error", IF(OR(AND($AT$6="",AT13<>""), ISTEXT($AT$6), ISTEXT(AT13), ISLOGICAL($AT$6), ISLOGICAL(AT13), ISERROR($AT$6), ISERROR(AT13)),"Error", IF(AT13>$AT$6,"Error", IF($AT$6=0,"",AT13/$AT$6*$AZ$7*$AW$7))))) -> 28.666667 | AX13: =IF(OR(D13="",AU13=""),"", IF($AU$6=0,"Error", IF(OR(AND($AU$6="",AU13<>""), ISTEXT($AU$6), ISTEXT(AU13), ISLOGICAL($AU$6), ISLOGICAL(AU13), ISERROR($AU$6), ISERROR(AU13)),"Error", IF(AU13>$AU$6,"Error", IF($AU$6=0,"",AU13/$AU$6*$AZ$7*$AX$7))))) -> 24.666667 | AY13: =IF(OR(D13="",AV13=""),"", IF($AV$6=0,"Error", IF(OR(AND($AV$6="",AV13<>""), ISTEXT($AV$6), ISTEXT(AV13), ISLOGICAL($AV$6), ISLOGICAL(AV13), ISERROR($AV$6), ISERROR(AV13)),"Error", IF(AV13>$AV$6,"Error", IF($AV$6=0,"",AV13/$AV$6*$AZ$7*$AY$7))))) | AZ13: =IF(D13="","",IF(COUNTIF(AW13:AY13,"Error")>0,"Error",IFERROR(IF(COUNT(AW13:AY13)=0,"",SUM(AW13:AY13)),""))) -> 53.333333 | BA13: =IFERROR(IF(D13="","",IF(AZ13="Error","Error",(AZ13*$BA$7))),"") -> 16 | BC13: =IF(OR(D13="",BB13=""),"",IF(BB13="Error","Error",IFERROR((BB13/$BB$6*$BC$6),""))) | BD13: =IF(AND(AY13="",BB13<>""),"Error",IF(BB13="","",IF(BB13>$BB$6,"Error",IF(BC13>=75,"Passed","Failed")))) | BE13: =_xlfn.LET( _xlpm.total,ROUND((N(AA13)+N(AS13)+N(BA13)),2), IF(OR(AA13="Error",AS13="Error",BA13="Error",BD13="Error"),"Error", IF(AND(AA13="",AS13="",BA13=""),"", IF(_xlpm.total>=70,_xlpm.total,IF(BD13="Passed",70,_xlpm.total))))) -> 73.9 | BF13: =IF(OR(AA13="Error",AS13="Error",BA13="Error",BD13="Error"),"Error", IF(D13="","", IF(AND(N($AA$6)+N($AS$6)+N($BA$7)=100%, OR(N($AA$6)=0,AA13<>""),OR(N($AS$6)=0,AS13<>""),OR(N($BA$7)=0,BA13<>""),BE13<>""), _xlfn.XLOOKUP(BE13,'Helper 1'!$B$3:$B$43,'Helper 1'!$D$3:$D$43,,-1),""))) -> 78 | BG13: {=_xlfn.LET( _xlpm.wWorks,$AA$6,_xlpm.pTask,$AS$6,_xlpm.examination,$BA$7, _xlpm.initialgrade,BE13,_xlpm.transmutedgrade,BF13,_xlpm.termExam,AY13, _xlpm.wWorkScore,AA13,_xlpm.pTaskScore,AS13,_xlpm.st1Score,AW13,_xlpm.st2Score,AX13,_xlpm.examScore,BA13,_xlpm.re,BD13, _xlpm.benchmark, _xlpm.wWorks*70*(_xlpm.wWorkScore<>"")+ _xlpm.pTask*70*(_xlpm.pTaskScore<>"")+ IF(_xlpm.wWorks+_xlpm.pTask<>100%, _xlpm.examination*21*((_xlpm.st1Score<>"")+(_xlpm.st2Score<>"")),0), _xlpm.remarks, _xlfn.IFS( N(_xlpm.transmutedgrade)>=90,"Passed [A]", N(_xlpm.transmutedgrade)>=80,"Passed [B]", N(_xlpm.transmutedgrade)>=75,"Passed [C]", N(_xlpm.transmutedgrade)>=65,"Failed [D]",TRUE,"Failed [E]"), IFERROR( IF(OR(_xlpm.wWorkScore="Error",_xlpm.pTaskScore="Error",_xlpm.examScore="Error",_xlpm.re="Error"),"Error", IF(_xlpm.transmutedgrade<>"", IF(_xlpm.wWorks+_xlpm.pTask=100%,_xlpm.remarks, IF(_xlpm.termExam="",IF(_xlpm.st2Score="", IF(_xlpm.initialgrade>=_xlpm.benchmark,"","At-Risk"), IF(N(_xlpm.transmutedgrade)<75,"At-Risk","")),_xlpm.remarks)), IF(_xlpm.initialgrade>=_xlpm.benchmark,"","At-Risk"))),""))}
B14: 6 | C14: =IF('Data Input'!M12="","",'Data Input'!M12) -> 2000504370 | D14: =IF(ISBLANK('Data Input'!N12),"",PROPER('Data Input'!N12)) -> Borja, Greedy | E14: 16 | F14: 12 | G14: 6 | H14: 20 | Y14: {=_xlfn.LET( _xlpm.score,E14:X14, _xlpm.limit,$E$6:$X$6, IF(OR(D14="",COUNTA(_xlpm.score)=0),"", IF(COUNTA(_xlpm.score,_xlpm.limit)=0,"", IF( OR( SUM((_xlpm.limit="")*(_xlpm.score<>""))>0, SUM(ISTEXT(_xlpm.limit)*1)>0, SUM(ISTEXT(_xlpm.score)*1)>0, SUM(ISLOGICAL(_xlpm.limit)*1)>0, SUM(ISLOGICAL(_xlpm.score)*1)>0, SUM(ISERROR(_xlpm.limit)*1)>0, SUM(ISERROR(_xlpm.score)*1)>0 ), "Error", IF( SUM((ISNUMBER(_xlpm.limit)*ISNUMBER(_xlpm.score)*(_xlpm.score>_xlpm.limit))*1)>0, "Error", IF(SUM(_xlpm.score)>$Y$6, "Error", SUM(_xlpm.score) ))))))} -> 54 | Z14: =IF(D14="","",IF(Y14="Error","Error",IFERROR((Y14/$Y$6*$Z$6),""))) -> 77.142857 | AA14: =IFERROR(IF(D14="","",IF(Z14="Error","Error",(Z14*$AA$6))),"") -> 15.428571 | AB14: 47 | AC14: 88 | AQ14: {=_xlfn.LET( _xlpm.score,AB14:AP14, _xlpm.limit,$AB$6:$AP$6, IF(OR(D14="",COUNTA(_xlpm.score)=0),"", IF(COUNTA(_xlpm.score,_xlpm.limit)=0,"", IF( OR( SUM((_xlpm.limit="")*(_xlpm.score<>""))>0, SUM(ISTEXT(_xlpm.limit)*1)>0, SUM(ISTEXT(_xlpm.score)*1)>0, SUM(ISLOGICAL(_xlpm.limit)*1)>0, SUM(ISLOGICAL(_xlpm.score)*1)>0, SUM(ISERROR(_xlpm.limit)*1)>0, SUM(ISERROR(_xlpm.score)*1)>0 ), "Error", IF( SUM((ISNUMBER(_xlpm.limit)*ISNUMBER(_xlpm.score)*(_xlpm.score>_xlpm.limit))*1)>0, "Error", IF(SUM(_xlpm.score)>$AQ$6, "Error", SUM(_xlpm.score) ))))))} -> 135 | AR14: =IF(D14="","",IF(AQ14="Error","Error",IFERROR((AQ14/$AQ$6*$AR$6),""))) -> 90 | AS14: =IFERROR(IF(D14="","",IF(AR14="Error","Error",(AR14*$AS$6))),"") -> 45 | AT14: 31 | AU14: 33 | AV14: 54 | AW14: =IF(OR(D14="",AT14=""),"", IF($AT$6=0,"Error", IF(OR(AND($AT$6="",AT14<>""), ISTEXT($AT$6), ISTEXT(AT14), ISLOGICAL($AT$6), ISLOGICAL(AT14), ISERROR($AT$6), ISERROR(AT14)),"Error", IF(AT14>$AT$6,"Error", IF($AT$6=0,"",AT14/$AT$6*$AZ$7*$AW$7))))) -> 20.666667 | AX14: =IF(OR(D14="",AU14=""),"", IF($AU$6=0,"Error", IF(OR(AND($AU$6="",AU14<>""), ISTEXT($AU$6), ISTEXT(AU14), ISLOGICAL($AU$6), ISLOGICAL(AU14), ISERROR($AU$6), ISERROR(AU14)),"Error", IF(AU14>$AU$6,"Error", IF($AU$6=0,"",AU14/$AU$6*$AZ$7*$AX$7))))) -> 22 | AY14: =IF(OR(D14="",AV14=""),"", IF($AV$6=0,"Error", IF(OR(AND($AV$6="",AV14<>""), ISTEXT($AV$6), ISTEXT(AV14), ISLOGICAL($AV$6), ISLOGICAL(AV14), ISERROR($AV$6), ISERROR(AV14)),"Error", IF(AV14>$AV$6,"Error", IF($AV$6=0,"",AV14/$AV$6*$AZ$7*$AY$7))))) -> 21.6 | AZ14: =IF(D14="","",IF(COUNTIF(AW14:AY14,"Error")>0,"Error",IFERROR(IF(COUNT(AW14:AY14)=0,"",SUM(AW14:AY14)),""))) -> 64.266667 | BA14: =IFERROR(IF(D14="","",IF(AZ14="Error","Error",(AZ14*$BA$7))),"") -> 19.28 | BC14: =IF(OR(D14="",BB14=""),"",IF(BB14="Error","Error",IFERROR((BB14/$BB$6*$BC$6),""))) | BD14: =IF(AND(AY14="",BB14<>""),"Error",IF(BB14="","",IF(BB14>$BB$6,"Error",IF(BC14>=75,"Passed","Failed")))) | BE14: =_xlfn.LET( _xlpm.total,ROUND((N(AA14)+N(AS14)+N(BA14)),2), IF(OR(AA14="Error",AS14="Error",BA14="Error",BD14="Error"),"Error", IF(AND(AA14="",AS14="",BA14=""),"", IF(_xlpm.total>=70,_xlpm.total,IF(BD14="Passed",70,_xlpm.total))))) -> 79.71 | BF14: =IF(OR(AA14="Error",AS14="Error",BA14="Error",BD14="Error"),"Error", IF(D14="","", IF(AND(N($AA$6)+N($AS$6)+N($BA$7)=100%, OR(N($AA$6)=0,AA14<>""),OR(N($AS$6)=0,AS14<>""),OR(N($BA$7)=0,BA14<>""),BE14<>""), _xlfn.XLOOKUP(BE14,'Helper 1'!$B$3:$B$43,'Helper 1'!$D$3:$D$43,,-1),""))) -> 83 | BG14: {=_xlfn.LET( _xlpm.wWorks,$AA$6,_xlpm.pTask,$AS$6,_xlpm.examination,$BA$7, _xlpm.initialgrade,BE14,_xlpm.transmutedgrade,BF14,_xlpm.termExam,AY14, _xlpm.wWorkScore,AA14,_xlpm.pTaskScore,AS14,_xlpm.st1Score,AW14,_xlpm.st2Score,AX14,_xlpm.examScore,BA14,_xlpm.re,BD14, _xlpm.benchmark, _xlpm.wWorks*70*(_xlpm.wWorkScore<>"")+ _xlpm.pTask*70*(_xlpm.pTaskScore<>"")+ IF(_xlpm.wWorks+_xlpm.pTask<>100%, _xlpm.examination*21*((_xlpm.st1Score<>"")+(_xlpm.st2Score<>"")),0), _xlpm.remarks, _xlfn.IFS( N(_xlpm.transmutedgrade)>=90,"Passed [A]", N(_xlpm.transmutedgrade)>=80,"Passed [B]", N(_xlpm.transmutedgrade)>=75,"Passed [C]", N(_xlpm.transmutedgrade)>=65,"Failed [D]",TRUE,"Failed [E]"), IFERROR( IF(OR(_xlpm.wWorkScore="Error",_xlpm.pTaskScore="Error",_xlpm.examScore="Error",_xlpm.re="Error"),"Error", IF(_xlpm.transmutedgrade<>"", IF(_xlpm.wWorks+_xlpm.pTask=100%,_xlpm.remarks, IF(_xlpm.termExam="",IF(_xlpm.st2Score="", IF(_xlpm.initialgrade>=_xlpm.benchmark,"","At-Risk"), IF(N(_xlpm.transmutedgrade)<75,"At-Risk","")),_xlpm.remarks)), IF(_xlpm.initialgrade>=_xlpm.benchmark,"","At-Risk"))),""))} -> Passed [B]
B15: 7 | C15: =IF('Data Input'!M13="","",'Data Input'!M13) -> 2000480420 | D15: =IF(ISBLANK('Data Input'!N13),"",PROPER('Data Input'!N13)) -> Cabalquinto, Juvy | E15: 6 | F15: 10 | G15: 6 | H15: 20 | Y15: {=_xlfn.LET( _xlpm.score,E15:X15, _xlpm.limit,$E$6:$X$6, IF(OR(D15="",COUNTA(_xlpm.score)=0),"", IF(COUNTA(_xlpm.score,_xlpm.limit)=0,"", IF( OR( SUM((_xlpm.limit="")*(_xlpm.score<>""))>0, SUM(ISTEXT(_xlpm.limit)*1)>0, SUM(ISTEXT(_xlpm.score)*1)>0, SUM(ISLOGICAL(_xlpm.limit)*1)>0, SUM(ISLOGICAL(_xlpm.score)*1)>0, SUM(ISERROR(_xlpm.limit)*1)>0, SUM(ISERROR(_xlpm.score)*1)>0 ), "Error", IF( SUM((ISNUMBER(_xlpm.limit)*ISNUMBER(_xlpm.score)*(_xlpm.score>_xlpm.limit))*1)>0, "Error", IF(SUM(_xlpm.score)>$Y$6, "Error", SUM(_xlpm.score) ))))))} -> 42 | Z15: =IF(D15="","",IF(Y15="Error","Error",IFERROR((Y15/$Y$6*$Z$6),""))) -> 60 | AA15: =IFERROR(IF(D15="","",IF(Z15="Error","Error",(Z15*$AA$6))),"") -> 12 | AB15: 45 | AC15: 88 | AQ15: {=_xlfn.LET( _xlpm.score,AB15:AP15, _xlpm.limit,$AB$6:$AP$6, IF(OR(D15="",COUNTA(_xlpm.score)=0),"", IF(COUNTA(_xlpm.score,_xlpm.limit)=0,"", IF( OR( SUM((_xlpm.limit="")*(_xlpm.score<>""))>0, SUM(ISTEXT(_xlpm.limit)*1)>0, SUM(ISTEXT(_xlpm.score)*1)>0, SUM(ISLOGICAL(_xlpm.limit)*1)>0, SUM(ISLOGICAL(_xlpm.score)*1)>0, SUM(ISERROR(_xlpm.limit)*1)>0, SUM(ISERROR(_xlpm.score)*1)>0 ), "Error", IF( SUM((ISNUMBER(_xlpm.limit)*ISNUMBER(_xlpm.score)*(_xlpm.score>_xlpm.limit))*1)>0, "Error", IF(SUM(_xlpm.score)>$AQ$6, "Error", SUM(_xlpm.score) ))))))} -> 133 | AR15: =IF(D15="","",IF(AQ15="Error","Error",IFERROR((AQ15/$AQ$6*$AR$6),""))) -> 88.666667 | AS15: =IFERROR(IF(D15="","",IF(AR15="Error","Error",(AR15*$AS$6))),"") -> 44.333333 | AT15: 31 | AU15: 32 | AV15: 44 | AW15: =IF(OR(D15="",AT15=""),"", IF($AT$6=0,"Error", IF(OR(AND($AT$6="",AT15<>""), ISTEXT($AT$6), ISTEXT(AT15), ISLOGICAL($AT$6), ISLOGICAL(AT15), ISERROR($AT$6), ISERROR(AT15)),"Error", IF(AT15>$AT$6,"Error", IF($AT$6=0,"",AT15/$AT$6*$AZ$7*$AW$7))))) -> 20.666667 | AX15: =IF(OR(D15="",AU15=""),"", IF($AU$6=0,"Error", IF(OR(AND($AU$6="",AU15<>""), ISTEXT($AU$6), ISTEXT(AU15), ISLOGICAL($AU$6), ISLOGICAL(AU15), ISERROR($AU$6), ISERROR(AU15)),"Error", IF(AU15>$AU$6,"Error", IF($AU$6=0,"",AU15/$AU$6*$AZ$7*$AX$7))))) -> 21.333333 | AY15: =IF(OR(D15="",AV15=""),"", IF($AV$6=0,"Error", IF(OR(AND($AV$6="",AV15<>""), ISTEXT($AV$6), ISTEXT(AV15), ISLOGICAL($AV$6), ISLOGICAL(AV15), ISERROR($AV$6), ISERROR(AV15)),"Error", IF(AV15>$AV$6,"Error", IF($AV$6=0,"",AV15/$AV$6*$AZ$7*$AY$7))))) -> 17.6 | AZ15: =IF(D15="","",IF(COUNTIF(AW15:AY15,"Error")>0,"Error",IFERROR(IF(COUNT(AW15:AY15)=0,"",SUM(AW15:AY15)),""))) -> 59.6 | BA15: =IFERROR(IF(D15="","",IF(AZ15="Error","Error",(AZ15*$BA$7))),"") -> 17.88 | BC15: =IF(OR(D15="",BB15=""),"",IF(BB15="Error","Error",IFERROR((BB15/$BB$6*$BC$6),""))) | BD15: =IF(AND(AY15="",BB15<>""),"Error",IF(BB15="","",IF(BB15>$BB$6,"Error",IF(BC15>=75,"Passed","Failed")))) | BE15: =_xlfn.LET( _xlpm.total,ROUND((N(AA15)+N(AS15)+N(BA15)),2), IF(OR(AA15="Error",AS15="Error",BA15="Error",BD15="Error"),"Error", IF(AND(AA15="",AS15="",BA15=""),"", IF(_xlpm.total>=70,_xlpm.total,IF(BD15="Passed",70,_xlpm.total))))) -> 74.21 | BF15: =IF(OR(AA15="Error",AS15="Error",BA15="Error",BD15="Error"),"Error", IF(D15="","", IF(AND(N($AA$6)+N($AS$6)+N($BA$7)=100%, OR(N($AA$6)=0,AA15<>""),OR(N($AS$6)=0,AS15<>""),OR(N($BA$7)=0,BA15<>""),BE15<>""), _xlfn.XLOOKUP(BE15,'Helper 1'!$B$3:$B$43,'Helper 1'!$D$3:$D$43,,-1),""))) -> 78 | BG15: {=_xlfn.LET( _xlpm.wWorks,$AA$6,_xlpm.pTask,$AS$6,_xlpm.examination,$BA$7, _xlpm.initialgrade,BE15,_xlpm.transmutedgrade,BF15,_xlpm.termExam,AY15, _xlpm.wWorkScore,AA15,_xlpm.pTaskScore,AS15,_xlpm.st1Score,AW15,_xlpm.st2Score,AX15,_xlpm.examScore,BA15,_xlpm.re,BD15, _xlpm.benchmark, _xlpm.wWorks*70*(_xlpm.wWorkScore<>"")+ _xlpm.pTask*70*(_xlpm.pTaskScore<>"")+ IF(_xlpm.wWorks+_xlpm.pTask<>100%, _xlpm.examination*21*((_xlpm.st1Score<>"")+(_xlpm.st2Score<>"")),0), _xlpm.remarks, _xlfn.IFS( N(_xlpm.transmutedgrade)>=90,"Passed [A]", N(_xlpm.transmutedgrade)>=80,"Passed [B]", N(_xlpm.transmutedgrade)>=75,"Passed [C]", N(_xlpm.transmutedgrade)>=65,"Failed [D]",TRUE,"Failed [E]"), IFERROR( IF(OR(_xlpm.wWorkScore="Error",_xlpm.pTaskScore="Error",_xlpm.examScore="Error",_xlpm.re="Error"),"Error", IF(_xlpm.transmutedgrade<>"", IF(_xlpm.wWorks+_xlpm.pTask=100%,_xlpm.remarks, IF(_xlpm.termExam="",IF(_xlpm.st2Score="", IF(_xlpm.initialgrade>=_xlpm.benchmark,"","At-Risk"), IF(N(_xlpm.transmutedgrade)<75,"At-Risk","")),_xlpm.remarks)), IF(_xlpm.initialgrade>=_xlpm.benchmark,"","At-Risk"))),""))} -> Passed [C]
B16: 8 | C16: =IF('Data Input'!M14="","",'Data Input'!M14) -> 2000487004 | D16: =IF(ISBLANK('Data Input'!N14),"",PROPER('Data Input'!N14)) -> Conlu, Marc Jeffrey | F16: 11 | G16: 4 | H16: 20 | Y16: {=_xlfn.LET( _xlpm.score,E16:X16, _xlpm.limit,$E$6:$X$6, IF(OR(D16="",COUNTA(_xlpm.score)=0),"", IF(COUNTA(_xlpm.score,_xlpm.limit)=0,"", IF( OR( SUM((_xlpm.limit="")*(_xlpm.score<>""))>0, SUM(ISTEXT(_xlpm.limit)*1)>0, SUM(ISTEXT(_xlpm.score)*1)>0, SUM(ISLOGICAL(_xlpm.limit)*1)>0, SUM(ISLOGICAL(_xlpm.score)*1)>0, SUM(ISERROR(_xlpm.limit)*1)>0, SUM(ISERROR(_xlpm.score)*1)>0 ), "Error", IF( SUM((ISNUMBER(_xlpm.limit)*ISNUMBER(_xlpm.score)*(_xlpm.score>_xlpm.limit))*1)>0, "Error", IF(SUM(_xlpm.score)>$Y$6, "Error", SUM(_xlpm.score) ))))))} -> 35 | Z16: =IF(D16="","",IF(Y16="Error","Error",IFERROR((Y16/$Y$6*$Z$6),""))) -> 50 | AA16: =IFERROR(IF(D16="","",IF(Z16="Error","Error",(Z16*$AA$6))),"") -> 10 | AB16: 45 | AC16: 88 | AQ16: {=_xlfn.LET( _xlpm.score,AB16:AP16, _xlpm.limit,$AB$6:$AP$6, IF(OR(D16="",COUNTA(_xlpm.score)=0),"", IF(COUNTA(_xlpm.score,_xlpm.limit)=0,"", IF( OR( SUM((_xlpm.limit="")*(_xlpm.score<>""))>0, SUM(ISTEXT(_xlpm.limit)*1)>0, SUM(ISTEXT(_xlpm.score)*1)>0, SUM(ISLOGICAL(_xlpm.limit)*1)>0, SUM(ISLOGICAL(_xlpm.score)*1)>0, SUM(ISERROR(_xlpm.limit)*1)>0, SUM(ISERROR(_xlpm.score)*1)>0 ), "Error", IF( SUM((ISNUMBER(_xlpm.limit)*ISNUMBER(_xlpm.score)*(_xlpm.score>_xlpm.limit))*1)>0, "Error", IF(SUM(_xlpm.score)>$AQ$6, "Error", SUM(_xlpm.score) ))))))} -> 133 | AR16: =IF(D16="","",IF(AQ16="Error","Error",IFERROR((AQ16/$AQ$6*$AR$6),""))) -> 88.666667 | AS16: =IFERROR(IF(D16="","",IF(AR16="Error","Error",(AR16*$AS$6))),"") -> 44.333333 | AT16: 29 | AU16: 41 | AV16: 53 | AW16: =IF(OR(D16="",AT16=""),"", IF($AT$6=0,"Error", IF(OR(AND($AT$6="",AT16<>""), ISTEXT($AT$6), ISTEXT(AT16), ISLOGICAL($AT$6), ISLOGICAL(AT16), ISERROR($AT$6), ISERROR(AT16)),"Error", IF(AT16>$AT$6,"Error", IF($AT$6=0,"",AT16/$AT$6*$AZ$7*$AW$7))))) -> 19.333333 | AX16: =IF(OR(D16="",AU16=""),"", IF($AU$6=0,"Error", IF(OR(AND($AU$6="",AU16<>""), ISTEXT($AU$6), ISTEXT(AU16), ISLOGICAL($AU$6), ISLOGICAL(AU16), ISERROR($AU$6), ISERROR(AU16)),"Error", IF(AU16>$AU$6,"Error", IF($AU$6=0,"",AU16/$AU$6*$AZ$7*$AX$7))))) -> 27.333333 | AY16: =IF(OR(D16="",AV16=""),"", IF($AV$6=0,"Error", IF(OR(AND($AV$6="",AV16<>""), ISTEXT($AV$6), ISTEXT(AV16), ISLOGICAL($AV$6), ISLOGICAL(AV16), ISERROR($AV$6), ISERROR(AV16)),"Error", IF(AV16>$AV$6,"Error", IF($AV$6=0,"",AV16/$AV$6*$AZ$7*$AY$7))))) -> 21.2 | AZ16: =IF(D16="","",IF(COUNTIF(AW16:AY16,"Error")>0,"Error",IFERROR(IF(COUNT(AW16:AY16)=0,"",SUM(AW16:AY16)),""))) -> 67.866667 | BA16: =IFERROR(IF(D16="","",IF(AZ16="Error","Error",(AZ16*$BA$7))),"") -> 20.36 | BC16: =IF(OR(D16="",BB16=""),"",IF(BB16="Error","Error",IFERROR((BB16/$BB$6*$BC$6),""))) | BD16: =IF(AND(AY16="",BB16<>""),"Error",IF(BB16="","",IF(BB16>$BB$6,"Error",IF(BC16>=75,"Passed","Failed")))) | BE16: =_xlfn.LET( _xlpm.total,ROUND((N(AA16)+N(AS16)+N(BA16)),2), IF(OR(AA16="Error",AS16="Error",BA16="Error",BD16="Error"),"Error", IF(AND(AA16="",AS16="",BA16=""),"", IF(_xlpm.total>=70,_xlpm.total,IF(BD16="Passed",70,_xlpm.total))))) -> 74.69 | BF16: =IF(OR(AA16="Error",AS16="Error",BA16="Error",BD16="Error"),"Error", IF(D16="","", IF(AND(N($AA$6)+N($AS$6)+N($BA$7)=100%, OR(N($AA$6)=0,AA16<>""),OR(N($AS$6)=0,AS16<>""),OR(N($BA$7)=0,BA16<>""),BE16<>""), _xlfn.XLOOKUP(BE16,'Helper 1'!$B$3:$B$43,'Helper 1'!$D$3:$D$43,,-1),""))) -> 78 | BG16: {=_xlfn.LET( _xlpm.wWorks,$AA$6,_xlpm.pTask,$AS$6,_xlpm.examination,$BA$7, _xlpm.initialgrade,BE16,_xlpm.transmutedgrade,BF16,_xlpm.termExam,AY16, _xlpm.wWorkScore,AA16,_xlpm.pTaskScore,AS16,_xlpm.st1Score,AW16,_xlpm.st2Score,AX16,_xlpm.examScore,BA16,_xlpm.re,BD16, _xlpm.benchmark, _xlpm.wWorks*70*(_xlpm.wWorkScore<>"")+ _xlpm.pTask*70*(_xlpm.pTaskScore<>"")+ IF(_xlpm.wWorks+_xlpm.pTask<>100%, _xlpm.examination*21*((_xlpm.st1Score<>"")+(_xlpm.st2Score<>"")),0), _xlpm.remarks, _xlfn.IFS( N(_xlpm.transmutedgrade)>=90,"Passed [A]", N(_xlpm.transmutedgrade)>=80,"Passed [B]", N(_xlpm.transmutedgrade)>=75,"Passed [C]", N(_xlpm.transmutedgrade)>=65,"Failed [D]",TRUE,"Failed [E]"), IFERROR( IF(OR(_xlpm.wWorkScore="Error",_xlpm.pTaskScore="Error",_xlpm.examScore="Error",_xlpm.re="Error"),"Error", IF(_xlpm.transmutedgrade<>"", IF(_xlpm.wWorks+_xlpm.pTask=100%,_xlpm.remarks, IF(_xlpm.termExam="",IF(_xlpm.st2Score="", IF(_xlpm.initialgrade>=_xlpm.benchmark,"","At-Risk"), IF(N(_xlpm.transmutedgrade)<75,"At-Risk","")),_xlpm.remarks)), IF(_xlpm.initialgrade>=_xlpm.benchmark,"","At-Risk"))),""))} -> Passed [C]
B17: 9 | C17: =IF('Data Input'!M15="","",'Data Input'!M15) -> 2000488434 | D17: =IF(ISBLANK('Data Input'!N15),"",PROPER('Data Input'!N15)) -> De Luna, Felicity Ryne | E17: 9 | F17: 1 | H17: 20 | Y17: {=_xlfn.LET( _xlpm.score,E17:X17, _xlpm.limit,$E$6:$X$6, IF(OR(D17="",COUNTA(_xlpm.score)=0),"", IF(COUNTA(_xlpm.score,_xlpm.limit)=0,"", IF( OR( SUM((_xlpm.limit="")*(_xlpm.score<>""))>0, SUM(ISTEXT(_xlpm.limit)*1)>0, SUM(ISTEXT(_xlpm.score)*1)>0, SUM(ISLOGICAL(_xlpm.limit)*1)>0, SUM(ISLOGICAL(_xlpm.score)*1)>0, SUM(ISERROR(_xlpm.limit)*1)>0, SUM(ISERROR(_xlpm.score)*1)>0 ), "Error", IF( SUM((ISNUMBER(_xlpm.limit)*ISNUMBER(_xlpm.score)*(_xlpm.score>_xlpm.limit))*1)>0, "Error", IF(SUM(_xlpm.score)>$Y$6, "Error", SUM(_xlpm.score) ))))))} -> 30 | Z17: =IF(D17="","",IF(Y17="Error","Error",IFERROR((Y17/$Y$6*$Z$6),""))) -> 42.857143 | AA17: =IFERROR(IF(D17="","",IF(Z17="Error","Error",(Z17*$AA$6))),"") -> 8.5714286 | AB17: 47 | AC17: 88 | AQ17: {=_xlfn.LET( _xlpm.score,AB17:AP17, _xlpm.limit,$AB$6:$AP$6, IF(OR(D17="",COUNTA(_xlpm.score)=0),"", IF(COUNTA(_xlpm.score,_xlpm.limit)=0,"", IF( OR( SUM((_xlpm.limit="")*(_xlpm.score<>""))>0, SUM(ISTEXT(_xlpm.limit)*1)>0, SUM(ISTEXT(_xlpm.score)*1)>0, SUM(ISLOGICAL(_xlpm.limit)*1)>0, SUM(ISLOGICAL(_xlpm.score)*1)>0, SUM(ISERROR(_xlpm.limit)*1)>0, SUM(ISERROR(_xlpm.score)*1)>0 ), "Error", IF( SUM((ISNUMBER(_xlpm.limit)*ISNUMBER(_xlpm.score)*(_xlpm.score>_xlpm.limit))*1)>0, "Error", IF(SUM(_xlpm.score)>$AQ$6, "Error", SUM(_xlpm.score) ))))))} -> 135 | AR17: =IF(D17="","",IF(AQ17="Error","Error",IFERROR((AQ17/$AQ$6*$AR$6),""))) -> 90 | AS17: =IFERROR(IF(D17="","",IF(AR17="Error","Error",(AR17*$AS$6))),"") -> 45 | AT17: 35 | AU17: 25 | AV17: 38 | AW17: =IF(OR(D17="",AT17=""),"", IF($AT$6=0,"Error", IF(OR(AND($AT$6="",AT17<>""), ISTEXT($AT$6), ISTEXT(AT17), ISLOGICAL($AT$6), ISLOGICAL(AT17), ISERROR($AT$6), ISERROR(AT17)),"Error", IF(AT17>$AT$6,"Error", IF($AT$6=0,"",AT17/$AT$6*$AZ$7*$AW$7))))) -> 23.333333 | AX17: =IF(OR(D17="",AU17=""),"", IF($AU$6=0,"Error", IF(OR(AND($AU$6="",AU17<>""), ISTEXT($AU$6), ISTEXT(AU17), ISLOGICAL($AU$6), ISLOGICAL(AU17), ISERROR($AU$6), ISERROR(AU17)),"Error", IF(AU17>$AU$6,"Error", IF($AU$6=0,"",AU17/$AU$6*$AZ$7*$AX$7))))) -> 16.666667 | AY17: =IF(OR(D17="",AV17=""),"", IF($AV$6=0,"Error", IF(OR(AND($AV$6="",AV17<>""), ISTEXT($AV$6), ISTEXT(AV17), ISLOGICAL($AV$6), ISLOGICAL(AV17), ISERROR($AV$6), ISERROR(AV17)),"Error", IF(AV17>$AV$6,"Error", IF($AV$6=0,"",AV17/$AV$6*$AZ$7*$AY$7))))) -> 15.2 | AZ17: =IF(D17="","",IF(COUNTIF(AW17:AY17,"Error")>0,"Error",IFERROR(IF(COUNT(AW17:AY17)=0,"",SUM(AW17:AY17)),""))) -> 55.2 | BA17: =IFERROR(IF(D17="","",IF(AZ17="Error","Error",(AZ17*$BA$7))),"") -> 16.56 | BC17: =IF(OR(D17="",BB17=""),"",IF(BB17="Error","Error",IFERROR((BB17/$BB$6*$BC$6),""))) | BD17: =IF(AND(AY17="",BB17<>""),"Error",IF(BB17="","",IF(BB17>$BB$6,"Error",IF(BC17>=75,"Passed","Failed")))) | BE17: =_xlfn.LET( _xlpm.total,ROUND((N(AA17)+N(AS17)+N(BA17)),2), IF(OR(AA17="Error",AS17="Error",BA17="Error",BD17="Error"),"Error", IF(AND(AA17="",AS17="",BA17=""),"", IF(_xlpm.total>=70,_xlpm.total,IF(BD17="Passed",70,_xlpm.total))))) -> 70.13 | BF17: =IF(OR(AA17="Error",AS17="Error",BA17="Error",BD17="Error"),"Error", IF(D17="","", IF(AND(N($AA$6)+N($AS$6)+N($BA$7)=100%, OR(N($AA$6)=0,AA17<>""),OR(N($AS$6)=0,AS17<>""),OR(N($BA$7)=0,BA17<>""),BE17<>""), _xlfn.XLOOKUP(BE17,'Helper 1'!$B$3:$B$43,'Helper 1'!$D$3:$D$43,,-1),""))) -> 75 | BG17: {=_xlfn.LET( _xlpm.wWorks,$AA$6,_xlpm.pTask,$AS$6,_xlpm.examination,$BA$7, _xlpm.initialgrade,BE17,_xlpm.transmutedgrade,BF17,_xlpm.termExam,AY17, _xlpm.wWorkScore,AA17,_xlpm.pTaskScore,AS17,_xlpm.st1Score,AW17,_xlpm.st2Score,AX17,_xlpm.examScore,BA17,_xlpm.re,BD17, _xlpm.benchmark, _xlpm.wWorks*70*(_xlpm.wWorkScore<>"")+ _xlpm.pTask*70*(_xlpm.pTaskScore<>"")+ IF(_xlpm.wWorks+_xlpm.pTask<>100%, _xlpm.examination*21*((_xlpm.st1Score<>"")+(_xlpm.st2Score<>"")),0), _xlpm.remarks, _xlfn.IFS( N(_xlpm.transmutedgrade)>=90,"Passed [A]", N(_xlpm.transmutedgrade)>=80,"Passed [B]", N(_xlpm.transmutedgrade)>=75,"Passed [C]", N(_xlpm.transmutedgrade)>=65,"Failed [D]",TRUE,"Failed [E]"), IFERROR( IF(OR(_xlpm.wWorkScore="Error",_xlpm.pTaskScore="Error",_xlpm.examScore="Error",_xlpm.re="Error"),"Error", IF(_xlpm.transmutedgrade<>"", IF(_xlpm.wWorks+_xlpm.pTask=100%,_xlpm.remarks, IF(_xlpm.termExam="",IF(_xlpm.st2Score="", IF(_xlpm.initialgrade>=_xlpm.benchmark,"","At-Risk"), IF(N(_xlpm.transmutedgrade)<75,"At-Risk","")),_xlpm.remarks)), IF(_xlpm.initialgrade>=_xlpm.benchmark,"","At-Risk"))),""))} -> Passed [C]
B18: 10 | C18: =IF('Data Input'!M16="","",'Data Input'!M16) -> 2000485973 | D18: =IF(ISBLANK('Data Input'!N16),"",PROPER('Data Input'!N16)) -> Delos Reyes, Gavin Zue | E18: 5 | F18: 16 | G18: 5 | H18: 20 | Y18: {=_xlfn.LET( _xlpm.score,E18:X18, _xlpm.limit,$E$6:$X$6, IF(OR(D18="",COUNTA(_xlpm.score)=0),"", IF(COUNTA(_xlpm.score,_xlpm.limit)=0,"", IF( OR( SUM((_xlpm.limit="")*(_xlpm.score<>""))>0, SUM(ISTEXT(_xlpm.limit)*1)>0, SUM(ISTEXT(_xlpm.score)*1)>0, SUM(ISLOGICAL(_xlpm.limit)*1)>0, SUM(ISLOGICAL(_xlpm.score)*1)>0, SUM(ISERROR(_xlpm.limit)*1)>0, SUM(ISERROR(_xlpm.score)*1)>0 ), "Error", IF( SUM((ISNUMBER(_xlpm.limit)*ISNUMBER(_xlpm.score)*(_xlpm.score>_xlpm.limit))*1)>0, "Error", IF(SUM(_xlpm.score)>$Y$6, "Error", SUM(_xlpm.score) ))))))} -> 46 | Z18: =IF(D18="","",IF(Y18="Error","Error",IFERROR((Y18/$Y$6*$Z$6),""))) -> 65.714286 | AA18: =IFERROR(IF(D18="","",IF(Z18="Error","Error",(Z18*$AA$6))),"") -> 13.142857 | AB18: 49 | AC18: 95 | AQ18: {=_xlfn.LET( _xlpm.score,AB18:AP18, _xlpm.limit,$AB$6:$AP$6, IF(OR(D18="",COUNTA(_xlpm.score)=0),"", IF(COUNTA(_xlpm.score,_xlpm.limit)=0,"", IF( OR( SUM((_xlpm.limit="")*(_xlpm.score<>""))>0, SUM(ISTEXT(_xlpm.limit)*1)>0, SUM(ISTEXT(_xlpm.score)*1)>0, SUM(ISLOGICAL(_xlpm.limit)*1)>0, SUM(ISLOGICAL(_xlpm.score)*1)>0, SUM(ISERROR(_xlpm.limit)*1)>0, SUM(ISERROR(_xlpm.score)*1)>0 ), "Error", IF( SUM((ISNUMBER(_xlpm.limit)*ISNUMBER(_xlpm.score)*(_xlpm.score>_xlpm.limit))*1)>0, "Error", IF(SUM(_xlpm.score)>$AQ$6, "Error", SUM(_xlpm.score) ))))))} -> 144 | AR18: =IF(D18="","",IF(AQ18="Error","Error",IFERROR((AQ18/$AQ$6*$AR$6),""))) -> 96 | AS18: =IFERROR(IF(D18="","",IF(AR18="Error","Error",(AR18*$AS$6))),"") -> 48 | AT18: 40 | AU18: 43 | AV18: 79 | AW18: =IF(OR(D18="",AT18=""),"", IF($AT$6=0,"Error", IF(OR(AND($AT$6="",AT18<>""), ISTEXT($AT$6), ISTEXT(AT18), ISLOGICAL($AT$6), ISLOGICAL(AT18), ISERROR($AT$6), ISERROR(AT18)),"Error", IF(AT18>$AT$6,"Error", IF($AT$6=0,"",AT18/$AT$6*$AZ$7*$AW$7))))) -> 26.666667 | AX18: =IF(OR(D18="",AU18=""),"", IF($AU$6=0,"Error", IF(OR(AND($AU$6="",AU18<>""), ISTEXT($AU$6), ISTEXT(AU18), ISLOGICAL($AU$6), ISLOGICAL(AU18), ISERROR($AU$6), ISERROR(AU18)),"Error", IF(AU18>$AU$6,"Error", IF($AU$6=0,"",AU18/$AU$6*$AZ$7*$AX$7))))) -> 28.666667 | AY18: =IF(OR(D18="",AV18=""),"", IF($AV$6=0,"Error", IF(OR(AND($AV$6="",AV18<>""), ISTEXT($AV$6), ISTEXT(AV18), ISLOGICAL($AV$6), ISLOGICAL(AV18), ISERROR($AV$6), ISERROR(AV18)),"Error", IF(AV18>$AV$6,"Error", IF($AV$6=0,"",AV18/$AV$6*$AZ$7*$AY$7))))) -> 31.6 | AZ18: =IF(D18="","",IF(COUNTIF(AW18:AY18,"Error")>0,"Error",IFERROR(IF(COUNT(AW18:AY18)=0,"",SUM(AW18:AY18)),""))) -> 86.933333 | BA18: =IFERROR(IF(D18="","",IF(AZ18="Error","Error",(AZ18*$BA$7))),"") -> 26.08 | BC18: =IF(OR(D18="",BB18=""),"",IF(BB18="Error","Error",IFERROR((BB18/$BB$6*$BC$6),""))) | BD18: =IF(AND(AY18="",BB18<>""),"Error",IF(BB18="","",IF(BB18>$BB$6,"Error",IF(BC18>=75,"Passed","Failed")))) | BE18: =_xlfn.LET( _xlpm.total,ROUND((N(AA18)+N(AS18)+N(BA18)),2), IF(OR(AA18="Error",AS18="Error",BA18="Error",BD18="Error"),"Error", IF(AND(AA18="",AS18="",BA18=""),"", IF(_xlpm.total>=70,_xlpm.total,IF(BD18="Passed",70,_xlpm.total))))) -> 87.22 | BF18: =IF(OR(AA18="Error",AS18="Error",BA18="Error",BD18="Error"),"Error", IF(D18="","", IF(AND(N($AA$6)+N($AS$6)+N($BA$7)=100%, OR(N($AA$6)=0,AA18<>""),OR(N($AS$6)=0,AS18<>""),OR(N($BA$7)=0,BA18<>""),BE18<>""), _xlfn.XLOOKUP(BE18,'Helper 1'!$B$3:$B$43,'Helper 1'!$D$3:$D$43,,-1),""))) -> 89 | BG18: {=_xlfn.LET( _xlpm.wWorks,$AA$6,_xlpm.pTask,$AS$6,_xlpm.examination,$BA$7, _xlpm.initialgrade,BE18,_xlpm.transmutedgrade,BF18,_xlpm.termExam,AY18, _xlpm.wWorkScore,AA18,_xlpm.pTaskScore,AS18,_xlpm.st1Score,AW18,_xlpm.st2Score,AX18,_xlpm.examScore,BA18,_xlpm.re,BD18, _xlpm.benchmark, _xlpm.wWorks*70*(_xlpm.wWorkScore<>"")+ _xlpm.pTask*70*(_xlpm.pTaskScore<>"")+ IF(_xlpm.wWorks+_xlpm.pTask<>100%, _xlpm.examination*21*((_xlpm.st1Score<>"")+(_xlpm.st2Score<>"")),0), _xlpm.remarks, _xlfn.IFS( N(_xlpm.transmutedgrade)>=90,"Passed [A]", N(_xlpm.transmutedgrade)>=80,"Passed [B]", N(_xlpm.transmutedgrade)>=75,"Passed [C]", N(_xlpm.transmutedgrade)>=65,"Failed [D]",TRUE,"Failed [E]"), IFERROR( IF(OR(_xlpm.wWorkScore="Error",_xlpm.pTaskScore="Error",_xlpm.examScore="Error",_xlpm.re="Error"),"Error", IF(_xlpm.transmutedgrade<>"", IF(_xlpm.wWorks+_xlpm.pTask=100%,_xlpm.remarks, IF(_xlpm.termExam="",IF(_xlpm.st2Score="", IF(_xlpm.initialgrade>=_xlpm.benchmark,"","At-Risk"), IF(N(_xlpm.transmutedgrade)<75,"At-Risk","")),_xlpm.remarks)), IF(_xlpm.initialgrade>=_xlpm.benchmark,"","At-Risk"))),""))} -> Passed [B]
B19: 11 | C19: =IF('Data Input'!M17="","",'Data Input'!M17) -> 2000486374 | D19: =IF(ISBLANK('Data Input'!N17),"",PROPER('Data Input'!N17)) -> Dianela, Mary Diane | E19: 18 | F19: 13 | G19: 4 | H19: 20 | Y19: {=_xlfn.LET( _xlpm.score,E19:X19, _xlpm.limit,$E$6:$X$6, IF(OR(D19="",COUNTA(_xlpm.score)=0),"", IF(COUNTA(_xlpm.score,_xlpm.limit)=0,"", IF( OR( SUM((_xlpm.limit="")*(_xlpm.score<>""))>0, SUM(ISTEXT(_xlpm.limit)*1)>0, SUM(ISTEXT(_xlpm.score)*1)>0, SUM(ISLOGICAL(_xlpm.limit)*1)>0, SUM(ISLOGICAL(_xlpm.score)*1)>0, SUM(ISERROR(_xlpm.limit)*1)>0, SUM(ISERROR(_xlpm.score)*1)>0 ), "Error", IF( SUM((ISNUMBER(_xlpm.limit)*ISNUMBER(_xlpm.score)*(_xlpm.score>_xlpm.limit))*1)>0, "Error", IF(SUM(_xlpm.score)>$Y$6, "Error", SUM(_xlpm.score) ))))))} -> 55 | Z19: =IF(D19="","",IF(Y19="Error","Error",IFERROR((Y19/$Y$6*$Z$6),""))) -> 78.571429 | AA19: =IFERROR(IF(D19="","",IF(Z19="Error","Error",(Z19*$AA$6))),"") -> 15.714286 | AB19: 50 | AC19: 93 | AQ19: {=_xlfn.LET( _xlpm.score,AB19:AP19, _xlpm.limit,$AB$6:$AP$6, IF(OR(D19="",COUNTA(_xlpm.score)=0),"", IF(COUNTA(_xlpm.score,_xlpm.limit)=0,"", IF( OR( SUM((_xlpm.limit="")*(_xlpm.score<>""))>0, SUM(ISTEXT(_xlpm.limit)*1)>0, SUM(ISTEXT(_xlpm.score)*1)>0, SUM(ISLOGICAL(_xlpm.limit)*1)>0, SUM(ISLOGICAL(_xlpm.score)*1)>0, SUM(ISERROR(_xlpm.limit)*1)>0, SUM(ISERROR(_xlpm.score)*1)>0 ), "Error", IF( SUM((ISNUMBER(_xlpm.limit)*ISNUMBER(_xlpm.score)*(_xlpm.score>_xlpm.limit))*1)>0, "Error", IF(SUM(_xlpm.score)>$AQ$6, "Error", SUM(_xlpm.score) ))))))} -> 143 | AR19: =IF(D19="","",IF(AQ19="Error","Error",IFERROR((AQ19/$AQ$6*$AR$6),""))) -> 95.333333 | AS19: =IFERROR(IF(D19="","",IF(AR19="Error","Error",(AR19*$AS$6))),"") -> 47.666667 | AT19: 38 | AU19: 35 | AV19: 50 | AW19: =IF(OR(D19="",AT19=""),"", IF($AT$6=0,"Error", IF(OR(AND($AT$6="",AT19<>""), ISTEXT($AT$6), ISTEXT(AT19), ISLOGICAL($AT$6), ISLOGICAL(AT19), ISERROR($AT$6), ISERROR(AT19)),"Error", IF(AT19>$AT$6,"Error", IF($AT$6=0,"",AT19/$AT$6*$AZ$7*$AW$7))))) -> 25.333333 | AX19: =IF(OR(D19="",AU19=""),"", IF($AU$6=0,"Error", IF(OR(AND($AU$6="",AU19<>""), ISTEXT($AU$6), ISTEXT(AU19), ISLOGICAL($AU$6), ISLOGICAL(AU19), ISERROR($AU$6), ISERROR(AU19)),"Error", IF(AU19>$AU$6,"Error", IF($AU$6=0,"",AU19/$AU$6*$AZ$7*$AX$7))))) -> 23.333333 | AY19: =IF(OR(D19="",AV19=""),"", IF($AV$6=0,"Error", IF(OR(AND($AV$6="",AV19<>""), ISTEXT($AV$6), ISTEXT(AV19), ISLOGICAL($AV$6), ISLOGICAL(AV19), ISERROR($AV$6), ISERROR(AV19)),"Error", IF(AV19>$AV$6,"Error", IF($AV$6=0,"",AV19/$AV$6*$AZ$7*$AY$7))))) -> 20 | AZ19: =IF(D19="","",IF(COUNTIF(AW19:AY19,"Error")>0,"Error",IFERROR(IF(COUNT(AW19:AY19)=0,"",SUM(AW19:AY19)),""))) -> 68.666667 | BA19: =IFERROR(IF(D19="","",IF(AZ19="Error","Error",(AZ19*$BA$7))),"") -> 20.6 | BC19: =IF(OR(D19="",BB19=""),"",IF(BB19="Error","Error",IFERROR((BB19/$BB$6*$BC$6),""))) | BD19: =IF(AND(AY19="",BB19<>""),"Error",IF(BB19="","",IF(BB19>$BB$6,"Error",IF(BC19>=75,"Passed","Failed")))) | BE19: =_xlfn.LET( _xlpm.total,ROUND((N(AA19)+N(AS19)+N(BA19)),2), IF(OR(AA19="Error",AS19="Error",BA19="Error",BD19="Error"),"Error", IF(AND(AA19="",AS19="",BA19=""),"", IF(_xlpm.total>=70,_xlpm.total,IF(BD19="Passed",70,_xlpm.total))))) -> 83.98 | BF19: =IF(OR(AA19="Error",AS19="Error",BA19="Error",BD19="Error"),"Error", IF(D19="","", IF(AND(N($AA$6)+N($AS$6)+N($BA$7)=100%, OR(N($AA$6)=0,AA19<>""),OR(N($AS$6)=0,AS19<>""),OR(N($BA$7)=0,BA19<>""),BE19<>""), _xlfn.XLOOKUP(BE19,'Helper 1'!$B$3:$B$43,'Helper 1'!$D$3:$D$43,,-1),""))) -> 86 | BG19: {=_xlfn.LET( _xlpm.wWorks,$AA$6,_xlpm.pTask,$AS$6,_xlpm.examination,$BA$7, _xlpm.initialgrade,BE19,_xlpm.transmutedgrade,BF19,_xlpm.termExam,AY19, _xlpm.wWorkScore,AA19,_xlpm.pTaskScore,AS19,_xlpm.st1Score,AW19,_xlpm.st2Score,AX19,_xlpm.examScore,BA19,_xlpm.re,BD19, _xlpm.benchmark, _xlpm.wWorks*70*(_xlpm.wWorkScore<>"")+ _xlpm.pTask*70*(_xlpm.pTaskScore<>"")+ IF(_xlpm.wWorks+_xlpm.pTask<>100%, _xlpm.examination*21*((_xlpm.st1Score<>"")+(_xlpm.st2Score<>"")),0), _xlpm.remarks, _xlfn.IFS( N(_xlpm.transmutedgrade)>=90,"Passed [A]", N(_xlpm.transmutedgrade)>=80,"Passed [B]", N(_xlpm.transmutedgrade)>=75,"Passed [C]", N(_xlpm.transmutedgrade)>=65,"Failed [D]",TRUE,"Failed [E]"), IFERROR( IF(OR(_xlpm.wWorkScore="Error",_xlpm.pTaskScore="Error",_xlpm.examScore="Error",_xlpm.re="Error"),"Error", IF(_xlpm.transmutedgrade<>"", IF(_xlpm.wWorks+_xlpm.pTask=100%,_xlpm.remarks, IF(_xlpm.termExam="",IF(_xlpm.st2Score="", IF(_xlpm.initialgrade>=_xlpm.benchmark,"","At-Risk"), IF(N(_xlpm.transmutedgrade)<75,"At-Risk","")),_xlpm.remarks)), IF(_xlpm.initialgrade>=_xlpm.benchmark,"","At-Risk"))),""))} -> Passed [B]
