Workbook
Name StudentNames: Input!$F$8:$F$57
Name TRANSMUTATION: TRANSMUTATION!$A$2:$B$13

Sheet Instructions
C3: P60 Class Record Instructions
C5: Settings Tab
C7: 1. Kindly input your class details as indicated in the row fields. A sample is shown below.
C15: 2. Grading components, such as major examinations and quizzes, are listed in each row along with their corresponding codes. Please enter the appropriate percentage for each component based on your course syllabus. Also, include the date in its designated column and indicate the highest possible score in the # of POINTS column. These details will reflect in the Input tab. A sample is shown below.
C35: Input Tab
C37: 1. Once the percentages and highest possible scores have been entered in the Settings tab, you may proceed to encode the grades in the Input tab. The information previously entered should now appear in the Input tab, as shown below.
C48: 2. Enter the student number and name in their respective columns. Once completed, begin entering the students’ actual scores in the appropriate columns. The table should appear as shown.
C60: 3. If the encoded score exceeds the highest possible score, the entry will be highlighted in red, as shown in the image below. Please correct the score to avoid errors in the computation at the end of each component. Once corrected, the grades will be computed as intended.
C73: Summary Tab
C75: 1. The Summary tab displays the computed grade for each grading period: Prelims, Midterms, Pre-Finals, and Finals.
C76: 2. At the end of each period, you are required to enter the percentage equivalent obtained by each student. Refer to the image below.

Sheet Settings
C3: STI Class Record P60 | D3: Branch | E3: Naga | O3: Class No. | P3: 1798
D4: Dept | E4: Hospitality Management | O4: Code | P4: GEDC1005
D5: SY | E5: 2026-2027 | O5: Section | P5: BSHM1A
D6: Sem | E6: 1st | O6: Room | P6: RM302
D7: Instructor | E7: John Marq E. Ramos | O7: Day | P7: MTh
D8: Subject | E8: Mathematics in the Modern World | O8: Time | P8: 1:00pm - 2:30pm
G11: PRELIMS | K11: MIDTERM | O11: PRE-FINALS | S11: FINALS
G12: % | H12: DATE | I12: # of POINTS | K12: % | L12: DATE | M12: # of POINTS | O12: % | P12: DATE | Q12: # of POINTS | S12: % | T12: DATE | U12: # of POINTS
C14: CLASS PARTICIPATION | G14: =G15+G20+G25 -> 0 | K14: =K15+K20+K25 -> 0 | O14: =SUM(O15,O20,O25) -> 0 | S14: =S15+S20+S25 -> 0
C15: Seatwork 1 | E15: SW1 | G15: 0 | K15: 0 | O15: 0 | S15: 0
C16: Seatwork 2 | E16: SW2
C17: Seatwork 3 | E17: SW3
C18: Seatwork 4 | E18: SW4
C19: Seatwork 5 | E19: SW5
C20: Homework 1 | E20: HW1
C21: Homework 2 | E21: HW2
C22: Homework 3 | E22: HW3
C23: Homework 4 | E23: HW4
C24: Homework 5 | E24: HW5
C25: Recitation 1 | E25: RC1 | G25: 0 | K25: 0 | O25: 0 | S25: 0
C26: Recitation 2 | E26: RC2
C27: Recitation 3 | E27: RC3
C28: PERFORMANCE TASKS
C29: Performance Task/Lab 1 | E29: PRC1 | G29: 0.3 | I29: 100 | K29: 0.3 | M29: 50 | O29: 0.3 | S29: 0.3
C30: Performance Task/Lab 2 | E30: PRC2 | I30: 100 | M30: 50
C31: Performance Task/Lab 3 | E31: PRC3 | I31: 50
C32: Performance Task/Lab 4 | E32: PRC4
C33: QUIZZES
C34: Quiz 1 | E34: Q1 | G34: 0.2 | I34: 100 | K34: 0.2 | M34: 10 | O34: 0.2 | S34: 0.2
C35: Quiz 2 | E35: Q2 | I35: 100 | M35: 20
C36: Quiz 3 | E36: Q3 | I36: 100 | M36: 35
C37: Quiz 4 | E37: Q4
C38: MAJOR EXAMINATION
C39: Exam | E39: EX | G39: 0.5 | H39: 46279 | I39: 70 | K39: 0.5 | M39: 70 | O39: 0.5 | S39: 0.5
G41: =SUM(G14,G29,G34,G39) -> 1 | K41: =SUM(K14,K29,K34,K39) -> 1 | O41: =SUM(O14,O29,O34,O39) -> 1 | S41: =SUM(S14,S29,S34,S39) -> 1

Sheet Input
D3: =Settings!E8&" - "&Settings!P5 -> Mathematics in the Modern World - BSHM1A | G3: PRELIMS | T3: MIDTERM | AG3: PRE-FINALS | AT3: FINALS
D4: =IF(Settings!P4="","",Settings!P4) -> GEDC1005 | G4: PT/LAB EXERCISES | K4: =Settings!G29 -> 0.3 | L4: QUIZZES | P4: =Settings!$G$34 -> 0.2 | Q4: EXAM | R4: =Settings!$G$39 -> 0.5 | T4: PT/LAB EXERCISES | X4: =Settings!K29 -> 0.3 | Y4: QUIZZES | AC4: =Settings!K34 -> 0.2 | AD4: EXAM | AE4: =Settings!K39 -> 0.5 | AG4: PT/LAB EXERCISES | AK4: =Settings!O29 -> 0.3 | AL4: QUIZZES | AP4: =Settings!O34 -> 0.2 | AQ4: EXAM | AR4: =Settings!O39 -> 0.5 | AT4: PT/LAB EXERCISES | AX4: =Settings!S29 -> 0.3 | AY4: QUIZZES | BC4: =Settings!S34 -> 0.2 | BD4: EXAM | BE4: =Settings!S39 -> 0.5
D5: A highlighted cell, as shown in the figure on the left, indicates that the score has exceeded the limit. | G5: =IF(Settings!$E29="","",Settings!$E29) -> PRC1 | H5: =IF(Settings!$E30="","",Settings!$E30) -> PRC2 | I5: =IF(Settings!$E31="","",Settings!$E31) -> PRC3 | J5: =IF(Settings!$E32="","",Settings!$E32) -> PRC4 | K5: TTL | L5: Q1 | M5: Q2 | N5: Q3 | O5: Q4 | P5: TTL | Q5: EX | R5: EQV | T5: =IF(Settings!$E29="","",Settings!$E29) -> PRC1 | U5: =IF(Settings!$E30="","",Settings!$E30) -> PRC2 | V5: =IF(Settings!$E31="","",Settings!$E31) -> PRC3 | W5: =IF(Settings!$E32="","",Settings!$E32) -> PRC4 | X5: TTL | Y5: Q1 | Z5: Q2 | AA5: Q3 | AB5: Q4 | AC5: TTL | AD5: EX | AE5: EQV | AG5: =IF(Settings!$E29="","",Settings!$E29) -> PRC1 | AH5: =IF(Settings!$E30="","",Settings!$E30) -> PRC2 | AI5: =IF(Settings!$E31="","",Settings!$E31) -> PRC3 | AJ5: =IF(Settings!$E32="","",Settings!$E32) -> PRC4 | AK5: TTL | AL5: Q1 | AM5: Q2 | AN5: Q3 | AO5: Q4 | AP5: TTL | AQ5: EX | AR5: EQV | AT5: =IF(Settings!$E29="","",Settings!$E29) -> PRC1 | AU5: =IF(Settings!$E30="","",Settings!$E30) -> PRC2 | AV5: =IF(Settings!$E31="","",Settings!$E31) -> PRC3 | AW5: =IF(Settings!$E32="","",Settings!$E32) -> PRC4 | AX5: TTL | AY5: Q1 | AZ5: Q2 | BA5: Q3 | BB5: Q4 | BC5: TTL | BD5: EX | BE5: EQV
G6: =IF(Settings!I29="","",Settings!I29) -> 100 | H6: =IF(Settings!I30="","",Settings!I30) -> 100 | I6: =IF(Settings!I31="","",Settings!I31) -> 50 | J6: =IF(Settings!I32="","",Settings!I32) | L6: =IF(Settings!I34="","",Settings!I34) -> 100 | M6: =IF(Settings!I35="","",Settings!I35) -> 100 | N6: =IF(Settings!I36="","",Settings!I36) -> 100 | O6: =IF(Settings!I37="","",Settings!I37) | Q6: =IF(Settings!I39="","",Settings!I39) -> 70 | T6: =IF(Settings!M29="","",Settings!M29) -> 50 | U6: =IF(Settings!M30="","",Settings!M30) -> 50 | V6: =IF(Settings!M31="","",Settings!M31) | W6: =IF(Settings!M32="","",Settings!M32) | Y6: =IF(Settings!M34="","",Settings!M34) -> 10 | Z6: =IF(Settings!M35="","",Settings!M35) -> 20 | AA6: =IF(Settings!M36="","",Settings!M36) -> 35 | AB6: =IF(Settings!M37="","",Settings!M37) | AD6: =IF(Settings!M39="","",Settings!M39) -> 70 | AG6: =IF(Settings!Q29="","",Settings!Q29) | AH6: =IF(Settings!Q30="","",Settings!Q30) | AI6: =IF(Settings!Q31="","",Settings!Q31) | AJ6: =IF(Settings!Q32="","",Settings!Q32) | AL6: =IF(Settings!Q34="","",Settings!Q34) | AM6: =IF(Settings!Q35="","",Settings!Q35) | AN6: =IF(Settings!Q36="","",Settings!Q36) | AO6: =IF(Settings!Q37="","",Settings!Q37) | AQ6: =IF(Settings!Q39="","",Settings!Q39) | AT6: =IF(Settings!U29="","",Settings!U29) | AU6: =IF(Settings!U30="","",Settings!U30) | AV6: =IF(Settings!U31="","",Settings!U31) | AW6: =IF(Settings!U32="","",Settings!U32) | AY6: =IF(Settings!U34="","",Settings!U34) | AZ6: =IF(Settings!U35="","",Settings!U35) | BA6: =IF(Settings!U36="","",Settings!U36) | BB6: =IF(Settings!U37="","",Settings!U37) | BD6: =IF(Settings!U39="","",Settings!U39)
D7: Student No. | F7: Student Name | G7: =IF(Settings!H29="","",Settings!H29) | H7: =IF(Settings!H30="","",Settings!H30) | I7: =IF(Settings!H31="","",Settings!H31) | J7: =IF(Settings!H32="","",Settings!H32) | K7: =SUM(G6:J6) -> 250 | L7: =IF(Settings!H34="","",Settings!H34) | M7: =IF(Settings!$H35="","",Settings!$H35) | N7: =IF(Settings!$H36="","",Settings!$H36) | O7: =IF(Settings!H37="","",Settings!H37) | P7: =SUM(L6:O6) -> 300 | Q7: =IF(Settings!H39="","",Settings!H39) -> 46279 | T7: =IF(Settings!L29="","",Settings!L29) | U7: =IF(Settings!L30="","",Settings!L30) | V7: =IF(Settings!L31="","",Settings!L31) | W7: =IF(Settings!L32="","",Settings!L32) | X7: =SUM(T6:W6) -> 100 | Y7: =IF(Settings!L34="","",Settings!L34) | Z7: =IF(Settings!L35="","",Settings!L35) | AA7: =IF(Settings!L36="","",Settings!L36) | AB7: =IF(Settings!L37="","",Settings!L37) | AC7: =SUM(Y6:AB6) -> 65 | AD7: =IF(Settings!L39="","",Settings!L39) | AG7: =IF(Settings!P29="","",Settings!P29) | AH7: =IF(Settings!P30="","",Settings!P30) | AI7: =IF(Settings!P31="","",Settings!P31) | AJ7: =IF(Settings!P32="","",Settings!P32) | AK7: =SUM(AG6:AJ6) -> 0 | AL7: =IF(Settings!P34="","",Settings!P34) | AM7: =IF(Settings!P35="","",Settings!P35) | AN7: =IF(Settings!P36="","",Settings!P36) | AO7: =IF(Settings!P37="","",Settings!P37) | AP7: =SUM(AL6:AO6) -> 0 | AQ7: =IF(Settings!P39="","",Settings!P39) | AT7: =IF(Settings!T29="","",Settings!T29) | AU7: =IF(Settings!T30="","",Settings!T30) | AV7: =IF(Settings!T31="","",Settings!T31) | AW7: =IF(Settings!T32="","",Settings!T32) | AX7: =SUM(AT6:AW6) -> 0 | AY7: =IF(Settings!T34="","",Settings!T34) | AZ7: =IF(Settings!T35="","",Settings!T35) | BA7: =IF(Settings!T36="","",Settings!T36) | BB7: =IF(Settings!T37="","",Settings!T37) | BC7: =SUM(AY6:BB6) -> 0 | BD7: =IF(Settings!T39="","",Settings!T39)
C8: =C7+1 -> 1 | D8: 02000500651 | F8: ADAO,ANGELICA MAE BAAL | G8: 100 | H8: 100 | I8: 48 | K8: =IF(OR(F8="",COUNTA(G8:J8)=0),"", IF(COUNTA(G8:J8,$G$6:$J$6)=0,"", IF(OR( AND($G$6="",G8<>""),AND(ISTEXT($G$6),$G$6<>""),AND(ISTEXT(G8),G8<>""), AND($H$6="",H8<>""),AND(ISTEXT($H$6),$H$6<>""),AND(ISTEXT(H8),H8<>""), AND($I$6="",I8<>""),AND(ISTEXT($I$6),$I$6<>""),AND(ISTEXT(I8),I8<>""), AND($J$6="",J8<>""),AND(ISTEXT($J$6),$J$6<>""),AND(ISTEXT(J8),J8<>"")),"Error", IF(OR( AND(ISNUMBER($G$6),ISNUMBER(G8),G8>$G$6), AND(ISNUMBER($H$6),ISNUMBER(H8),H8>$H$6), AND(ISNUMBER($I$6),ISNUMBER(I8),I8>$I$6), AND(ISNUMBER($J$6),ISNUMBER(J8),J8>$J$6)),"Error", IF(SUM(G8:J8)>$K$7,"Error", SUM(G8:J8)))))) -> 248 | L8: 100 | M8: 100 | N8: 100 | P8: =IF(OR(F8="",COUNTA(L8:O8)=0),"", IF(COUNTA(L8:O8,$L$6:$O$6)=0,"", IF(OR( AND($L$6="",L8<>""),AND(ISTEXT($L$6),$L$6<>""),AND(ISTEXT(L8),L8<>""), AND($M$6="",M8<>""),AND(ISTEXT($M$6),$M$6<>""),AND(ISTEXT(M8),M8<>""), AND($N$6="",N8<>""),AND(ISTEXT($N$6),$N$6<>""),AND(ISTEXT(N8),N8<>""), AND($O$6="",O8<>""),AND(ISTEXT($O$6),$O$6<>""),AND(ISTEXT(O8),O8<>"")),"Error", IF(OR( AND(ISNUMBER($L$6),ISNUMBER(L8),L8>$L$6), AND(ISNUMBER($M$6),ISNUMBER(M8),M8>$M$6), AND(ISNUMBER($N$6),ISNUMBER(N8),N8>$N$6), AND(ISNUMBER($O$6),ISNUMBER(O8),O8>$O$6)),"Error", IF(SUM(L8:O8)>$P$7,"Error", SUM(L8:O8)))))) -> 300 | Q8: 30 | R8: =IF(F8="","", IF(AND(Q8="",$Q$6=""),"", IF($Q$6="","Error", IF(OR(AND(ISTEXT(Q8),Q8<>""),AND(ISTEXT($Q$6),$Q$6<>"")),"Error", IF(AND(ISNUMBER(Q8),ISNUMBER($Q$6),Q8>$Q$6),"Error", IFERROR(IF(Q8="","",(Q8/$Q$6)*100),0)))))) -> 42.857143 | T8: 50 | U8: 50 | X8: =IF(OR(F8="",COUNTA(T8:W8)=0),"", IF(COUNTA(T8:W8,$T$6:$W$6)=0,"", IF(OR( AND($T$6="",T8<>""),AND(ISTEXT($T$6),$T$6<>""),AND(ISTEXT(T8),T8<>""), AND($U$6="",U8<>""),AND(ISTEXT($U$6),$U$6<>""),AND(ISTEXT(U8),U8<>""), AND($V$6="",V8<>""),AND(ISTEXT($V$6),$V$6<>""),AND(ISTEXT(V8),V8<>""), AND($W$6="",W8<>""),AND(ISTEXT($W$6),$W$6<>""),AND(ISTEXT(W8),W8<>"")),"Error", IF(OR( AND(ISNUMBER($T$6),ISNUMBER(T8),T8>$T$6), AND(ISNUMBER($U$6),ISNUMBER(U8),U8>$U$6), AND(ISNUMBER($V$6),ISNUMBER(V8),V8>$V$6), AND(ISNUMBER($W$6),ISNUMBER(W8),W8>$W$6)),"Error", IF(SUM(T8:W8)>$X$7,"Error", SUM(T8:W8)))))) -> 100 | Y8: 5 | Z8: 18 | AA8: 15 | AC8: =IF(OR(F8="",COUNTA(Y8:AB8)=0),"", IF(COUNTA(Y8:AB8,$Y$6:$AB$6)=0,"", IF(OR( AND($Y$6="",Y8<>""),AND(ISTEXT($Y$6),$Y$6<>""),AND(ISTEXT(Y8),Y8<>""), AND($Z$6="",Z8<>""),AND(ISTEXT($Z$6),$Z$6<>""),AND(ISTEXT(Z8),Z8<>""), AND($AA$6="",AA8<>""),AND(ISTEXT($AA$6),$AA$6<>""),AND(ISTEXT(AA8),AA8<>""), AND($AB$6="",AB8<>""),AND(ISTEXT($AB$6),$AB$6<>""),AND(ISTEXT(AB8),AB8<>"")),"Error", IF(OR( AND(ISNUMBER($Y$6),ISNUMBER(Y8),Y8>$Y$6), AND(ISNUMBER($Z$6),ISNUMBER(Z8),Z8>$Z$6), AND(ISNUMBER($AA$6),ISNUMBER(AA8),AA8>$AA$6), AND(ISNUMBER($AB$6),ISNUMBER(AB8),AB8>$AB$6)),"Error", IF(SUM(Y8:AB8)>$AC$7,"Error", SUM(Y8:AB8)))))) -> 38 | AD8: 34 | AE8: =IF(F8="","", IF(AND(AD8="",$AD$6=""),"", IF($AD$6="","Error", IF(OR(AND(ISTEXT(AD8),AD8<>""),AND(ISTEXT($AD$6),$AD$6<>"")),"Error", IF(AND(ISNUMBER(AD8),ISNUMBER($AD$6),AD8>$AD$6),"Error", IFERROR(IF(AD8="","",(AD8/$AD$6)*100),0)))))) -> 48.571429 | AK8: =IF(OR(F8="",COUNTA(AG8:AJ8)=0),"", IF(COUNTA(AG8:AJ8,$AG$6:$AJ$6)=0,"", IF(OR( AND($AG$6="",AG8<>""),AND(ISTEXT($AG$6),$AG$6<>""),AND(ISTEXT(AG8),AG8<>""), AND($AH$6="",AH8<>""),AND(ISTEXT($AH$6),$AH$6<>""),AND(ISTEXT(AH8),AH8<>""), AND($AI$6="",AI8<>""),AND(ISTEXT($AI$6),$AI$6<>""),AND(ISTEXT(AI8),AI8<>""), AND($AJ$6="",AJ8<>""),AND(ISTEXT($AJ$6),$AJ$6<>""),AND(ISTEXT(AJ8),AJ8<>"")),"Error", IF(OR( AND(ISNUMBER($AG$6),ISNUMBER(AG8),AG8>$AG$6), AND(ISNUMBER($AH$6),ISNUMBER(AH8),AH8>$AH$6), AND(ISNUMBER($AI$6),ISNUMBER(AI8),AI8>$AI$6), AND(ISNUMBER($AJ$6),ISNUMBER(AJ8),AJ8>$AJ$6)),"Error", IF(SUM(AG8:AJ8)>$AK$7,"Error", SUM(AG8:AJ8)))))) | AP8: =IF(OR(F8="",COUNTA(AL8:AO8)=0),"", IF(COUNTA(AL8:AO8,$AL$6:$AO$6)=0,"", IF(OR( AND($AL$6="",AL8<>""),AND(ISTEXT($AL$6),$AL$6<>""),AND(ISTEXT(AL8),AL8<>""), AND($AM$6="",AM8<>""),AND(ISTEXT($AM$6),$AM$6<>""),AND(ISTEXT(AM8),AM8<>""), AND($AN$6="",AN8<>""),AND(ISTEXT($AN$6),$AN$6<>""),AND(ISTEXT(AN8),AN8<>""), AND($AO$6="",AO8<>""),AND(ISTEXT($AO$6),$AO$6<>""),AND(ISTEXT(AO8),AO8<>"")),"Error", IF(OR( AND(ISNUMBER($AL$6),ISNUMBER(AL8),AL8>$AL$6), AND(ISNUMBER($AM$6),ISNUMBER(AM8),AM8>$AM$6), AND(ISNUMBER($AN$6),ISNUMBER(AN8),AN8>$AN$6), AND(ISNUMBER($AO$6),ISNUMBER(AO8),AO8>$AO$6)),"Error", IF(SUM(AL8:AO8)>$AP$7,"Error", SUM(AL8:AO8)))))) | AR8: =IF(F8="","", IF(AND(AQ8="",$AQ$6=""),"", IF($AQ$6="","Error", IF(OR(AND(ISTEXT(AQ8),AQ8<>""),AND(ISTEXT($AQ$6),$AQ$6<>"")),"Error", IF(AND(ISNUMBER(AQ8),ISNUMBER($AQ$6),AD8>$AQ$6),"Error", IFERROR(IF(AQ8="","",(AQ8/$AQ$6)*100),0)))))) | AX8: =IF(OR(F8="",COUNTA(AT8:AW8)=0),"", IF(COUNTA(AT8:AW8,$AT$6:$AW$6)=0,"", IF(OR( AND($AT$6="",AT8<>""),AND(ISTEXT($AT$6),$AT$6<>""),AND(ISTEXT(AT8),AT8<>""), AND($AU$6="",AU8<>""),AND(ISTEXT($AU$6),$AU$6<>""),AND(ISTEXT(AU8),AU8<>""), AND($AV$6="",AV8<>""),AND(ISTEXT($AV$6),$AV$6<>""),AND(ISTEXT(AV8),AV8<>""), AND($AW$6="",AW8<>""),AND(ISTEXT($AW$6),$AW$6<>""),AND(ISTEXT(AW8),AW8<>"")),"Error", IF(OR( AND(ISNUMBER($AT$6),ISNUMBER(AT8),AT8>$AT$6), AND(ISNUMBER($AU$6),ISNUMBER(AU8),AU8>$AU$6), AND(ISNUMBER($AV$6),ISNUMBER(AV8),AV8>$AV$6), AND(ISNUMBER($AW$6),ISNUMBER(AW8),AW8>$AW$6)),"Error", IF(SUM(AT8:AW8)>$AX$7,"Error", SUM(AT8:AW8)))))) | BC8: =IF(OR(F8="",COUNTA(AY8:BB8)=0),"", IF(COUNTA(AY8:BB8,$AY$6:$BB$6)=0,"", IF(OR( AND($AY$6="",AY8<>""),AND(ISTEXT($AY$6),$AY$6<>""),AND(ISTEXT(AY8),AY8<>""), AND($AZ$6="",AZ8<>""),AND(ISTEXT($AZ$6),$AZ$6<>""),AND(ISTEXT(AZ8),AZ8<>""), AND($BA$6="",BA8<>""),AND(ISTEXT($BA$6),$BA$6<>""),AND(ISTEXT(BA8),BA8<>""), AND($BB$6="",BB8<>""),AND(ISTEXT($BB$6),$BB$6<>""),AND(ISTEXT(BB8),BB8<>"")),"Error", IF(OR( AND(ISNUMBER($AY$6),ISNUMBER(AY8),AY8>$AY$6), AND(ISNUMBER($AZ$6),ISNUMBER(AZ8),AZ8>$AZ$6), AND(ISNUMBER($BA$6),ISNUMBER(BA8),BA8>$BA$6), AND(ISNUMBER($BB$6),ISNUMBER(BB8),BB8>$BB$6)),"Error", IF(SUM(AY8:BB8)>$BC$7,"Error", SUM(AY8:BB8)))))) | BE8: =IF(F8="","", IF(AND(BD8="",$BD$6=""),"", IF($BD$6="","Error", IF(OR(AND(ISTEXT(BD8),BD8<>""),AND(ISTEXT($BD$6),$BD$6<>"")),"Error", IF(AND(ISNUMBER(BD8),ISNUMBER($BD$6),BD8>$BD$6),"Error", IFERROR(IF(BD8="","",(BD8/$BD$6)*100),0))))))
C9: =C8+1 -> 2 | D9: 02000508012 | F9: AMELANO,EUNICE MAE LUMBRE | G9: 98 | H9: 98 | I9: 47 | K9: =IF(OR(F9="",COUNTA(G9:J9)=0),"", IF(COUNTA(G9:J9,$G$6:$J$6)=0,"", IF(OR( AND($G$6="",G9<>""),AND(ISTEXT($G$6),$G$6<>""),AND(ISTEXT(G9),G9<>""), AND($H$6="",H9<>""),AND(ISTEXT($H$6),$H$6<>""),AND(ISTEXT(H9),H9<>""), AND($I$6="",I9<>""),AND(ISTEXT($I$6),$I$6<>""),AND(ISTEXT(I9),I9<>""), AND($J$6="",J9<>""),AND(ISTEXT($J$6),$J$6<>""),AND(ISTEXT(J9),J9<>"")),"Error", IF(OR( AND(ISNUMBER($G$6),ISNUMBER(G9),G9>$G$6), AND(ISNUMBER($H$6),ISNUMBER(H9),H9>$H$6), AND(ISNUMBER($I$6),ISNUMBER(I9),I9>$I$6), AND(ISNUMBER($J$6),ISNUMBER(J9),J9>$J$6)),"Error", IF(SUM(G9:J9)>$K$7,"Error", SUM(G9:J9)))))) -> 243 | L9: 98 | M9: 98 | N9: 98 | P9: =IF(OR(F9="",COUNTA(L9:O9)=0),"", IF(COUNTA(L9:O9,$L$6:$O$6)=0,"", IF(OR( AND($L$6="",L9<>""),AND(ISTEXT($L$6),$L$6<>""),AND(ISTEXT(L9),L9<>""), AND($M$6="",M9<>""),AND(ISTEXT($M$6),$M$6<>""),AND(ISTEXT(M9),M9<>""), AND($N$6="",N9<>""),AND(ISTEXT($N$6),$N$6<>""),AND(ISTEXT(N9),N9<>""), AND($O$6="",O9<>""),AND(ISTEXT($O$6),$O$6<>""),AND(ISTEXT(O9),O9<>"")),"Error", IF(OR( AND(ISNUMBER($L$6),ISNUMBER(L9),L9>$L$6), AND(ISNUMBER($M$6),ISNUMBER(M9),M9>$M$6), AND(ISNUMBER($N$6),ISNUMBER(N9),N9>$N$6), AND(ISNUMBER($O$6),ISNUMBER(O9),O9>$O$6)),"Error", IF(SUM(L9:O9)>$P$7,"Error", SUM(L9:O9)))))) -> 294 | Q9: 58 | R9: =IF(F9="","", IF(AND(Q9="",$Q$6=""),"", IF($Q$6="","Error", IF(OR(AND(ISTEXT(Q9),Q9<>""),AND(ISTEXT($Q$6),$Q$6<>"")),"Error", IF(AND(ISNUMBER(Q9),ISNUMBER($Q$6),Q9>$Q$6),"Error", IFERROR(IF(Q9="","",(Q9/$Q$6)*100),0)))))) -> 82.857143 | T9: 50 | U9: 50 | X9: =IF(OR(F9="",COUNTA(T9:W9)=0),"", IF(COUNTA(T9:W9,$T$6:$W$6)=0,"", IF(OR( AND($T$6="",T9<>""),AND(ISTEXT($T$6),$T$6<>""),AND(ISTEXT(T9),T9<>""), AND($U$6="",U9<>""),AND(ISTEXT($U$6),$U$6<>""),AND(ISTEXT(U9),U9<>""), AND($V$6="",V9<>""),AND(ISTEXT($V$6),$V$6<>""),AND(ISTEXT(V9),V9<>""), AND($W$6="",W9<>""),AND(ISTEXT($W$6),$W$6<>""),AND(ISTEXT(W9),W9<>"")),"Error", IF(OR( AND(ISNUMBER($T$6),ISNUMBER(T9),T9>$T$6), AND(ISNUMBER($U$6),ISNUMBER(U9),U9>$U$6), AND(ISNUMBER($V$6),ISNUMBER(V9),V9>$V$6), AND(ISNUMBER($W$6),ISNUMBER(W9),W9>$W$6)),"Error", IF(SUM(T9:W9)>$X$7,"Error", SUM(T9:W9)))))) -> 100 | Y9: 8 | Z9: 18 | AA9: 26 | AC9: =IF(OR(F9="",COUNTA(Y9:AB9)=0),"", IF(COUNTA(Y9:AB9,$Y$6:$AB$6)=0,"", IF(OR( AND($Y$6="",Y9<>""),AND(ISTEXT($Y$6),$Y$6<>""),AND(ISTEXT(Y9),Y9<>""), AND($Z$6="",Z9<>""),AND(ISTEXT($Z$6),$Z$6<>""),AND(ISTEXT(Z9),Z9<>""), AND($AA$6="",AA9<>""),AND(ISTEXT($AA$6),$AA$6<>""),AND(ISTEXT(AA9),AA9<>""), AND($AB$6="",AB9<>""),AND(ISTEXT($AB$6),$AB$6<>""),AND(ISTEXT(AB9),AB9<>"")),"Error", IF(OR( AND(ISNUMBER($Y$6),ISNUMBER(Y9),Y9>$Y$6), AND(ISNUMBER($Z$6),ISNUMBER(Z9),Z9>$Z$6), AND(ISNUMBER($AA$6),ISNUMBER(AA9),AA9>$AA$6), AND(ISNUMBER($AB$6),ISNUMBER(AB9),AB9>$AB$6)),"Error", IF(SUM(Y9:AB9)>$AC$7,"Error", SUM(Y9:AB9)))))) -> 52 | AD9: 48 | AE9: =IF(F9="","", IF(AND(AD9="",$AD$6=""),"", IF($AD$6="","Error", IF(OR(AND(ISTEXT(AD9),AD9<>""),AND(ISTEXT($AD$6),$AD$6<>"")),"Error", IF(AND(ISNUMBER(AD9),ISNUMBER($AD$6),AD9>$AD$6),"Error", IFERROR(IF(AD9="","",(AD9/$AD$6)*100),0)))))) -> 68.571429 | AK9: =IF(OR(F9="",COUNTA(AG9:AJ9)=0),"", IF(COUNTA(AG9:AJ9,$AG$6:$AJ$6)=0,"", IF(OR( AND($AG$6="",AG9<>""),AND(ISTEXT($AG$6),$AG$6<>""),AND(ISTEXT(AG9),AG9<>""), AND($AH$6="",AH9<>""),AND(ISTEXT($AH$6),$AH$6<>""),AND(ISTEXT(AH9),AH9<>""), AND($AI$6="",AI9<>""),AND(ISTEXT($AI$6),$AI$6<>""),AND(ISTEXT(AI9),AI9<>""), AND($AJ$6="",AJ9<>""),AND(ISTEXT($AJ$6),$AJ$6<>""),AND(ISTEXT(AJ9),AJ9<>"")),"Error", IF(OR( AND(ISNUMBER($AG$6),ISNUMBER(AG9),AG9>$AG$6), AND(ISNUMBER($AH$6),ISNUMBER(AH9),AH9>$AH$6), AND(ISNUMBER($AI$6),ISNUMBER(AI9),AI9>$AI$6), AND(ISNUMBER($AJ$6),ISNUMBER(AJ9),AJ9>$AJ$6)),"Error", IF(SUM(AG9:AJ9)>$AK$7,"Error", SUM(AG9:AJ9)))))) | AP9: =IF(OR(F9="",COUNTA(AL9:AO9)=0),"", IF(COUNTA(AL9:AO9,$AL$6:$AO$6)=0,"", IF(OR( AND($AL$6="",AL9<>""),AND(ISTEXT($AL$6),$AL$6<>""),AND(ISTEXT(AL9),AL9<>""), AND($AM$6="",AM9<>""),AND(ISTEXT($AM$6),$AM$6<>""),AND(ISTEXT(AM9),AM9<>""), AND($AN$6="",AN9<>""),AND(ISTEXT($AN$6),$AN$6<>""),AND(ISTEXT(AN9),AN9<>""), AND($AO$6="",AO9<>""),AND(ISTEXT($AO$6),$AO$6<>""),AND(ISTEXT(AO9),AO9<>"")),"Error", IF(OR( AND(ISNUMBER($AL$6),ISNUMBER(AL9),AL9>$AL$6), AND(ISNUMBER($AM$6),ISNUMBER(AM9),AM9>$AM$6), AND(ISNUMBER($AN$6),ISNUMBER(AN9),AN9>$AN$6), AND(ISNUMBER($AO$6),ISNUMBER(AO9),AO9>$AO$6)),"Error", IF(SUM(AL9:AO9)>$AP$7,"Error", SUM(AL9:AO9)))))) | AR9: =IF(F9="","", IF(AND(AQ9="",$AQ$6=""),"", IF($AQ$6="","Error", IF(OR(AND(ISTEXT(AQ9),AQ9<>""),AND(ISTEXT($AQ$6),$AQ$6<>"")),"Error", IF(AND(ISNUMBER(AQ9),ISNUMBER($AQ$6),AD9>$AQ$6),"Error", IFERROR(IF(AQ9="","",(AQ9/$AQ$6)*100),0)))))) | AX9: =IF(OR(F9="",COUNTA(AT9:AW9)=0),"", IF(COUNTA(AT9:AW9,$AT$6:$AW$6)=0,"", IF(OR( AND($AT$6="",AT9<>""),AND(ISTEXT($AT$6),$AT$6<>""),AND(ISTEXT(AT9),AT9<>""), AND($AU$6="",AU9<>""),AND(ISTEXT($AU$6),$AU$6<>""),AND(ISTEXT(AU9),AU9<>""), AND($AV$6="",AV9<>""),AND(ISTEXT($AV$6),$AV$6<>""),AND(ISTEXT(AV9),AV9<>""), AND($AW$6="",AW9<>""),AND(ISTEXT($AW$6),$AW$6<>""),AND(ISTEXT(AW9),AW9<>"")),"Error", IF(OR( AND(ISNUMBER($AT$6),ISNUMBER(AT9),AT9>$AT$6), AND(ISNUMBER($AU$6),ISNUMBER(AU9),AU9>$AU$6), AND(ISNUMBER($AV$6),ISNUMBER(AV9),AV9>$AV$6), AND(ISNUMBER($AW$6),ISNUMBER(AW9),AW9>$AW$6)),"Error", IF(SUM(AT9:AW9)>$AX$7,"Error", SUM(AT9:AW9)))))) | BC9: =IF(OR(F9="",COUNTA(AY9:BB9)=0),"", IF(COUNTA(AY9:BB9,$AY$6:$BB$6)=0,"", IF(OR( AND($AY$6="",AY9<>""),AND(ISTEXT($AY$6),$AY$6<>""),AND(ISTEXT(AY9),AY9<>""), AND($AZ$6="",AZ9<>""),AND(ISTEXT($AZ$6),$AZ$6<>""),AND(ISTEXT(AZ9),AZ9<>""), AND($BA$6="",BA9<>""),AND(ISTEXT($BA$6),$BA$6<>""),AND(ISTEXT(BA9),BA9<>""), AND($BB$6="",BB9<>""),AND(ISTEXT($BB$6),$BB$6<>""),AND(ISTEXT(BB9),BB9<>"")),"Error", IF(OR( AND(ISNUMBER($AY$6),ISNUMBER(AY9),AY9>$AY$6), AND(ISNUMBER($AZ$6),ISNUMBER(AZ9),AZ9>$AZ$6), AND(ISNUMBER($BA$6),ISNUMBER(BA9),BA9>$BA$6), AND(ISNUMBER($BB$6),ISNUMBER(BB9),BB9>$BB$6)),"Error", IF(SUM(AY9:BB9)>$BC$7,"Error", SUM(AY9:BB9)))))) | BE9: =IF(F9="","", IF(AND(BD9="",$BD$6=""),"", IF($BD$6="","Error", IF(OR(AND(ISTEXT(BD9),BD9<>""),AND(ISTEXT($BD$6),$BD$6<>"")),"Error", IF(AND(ISNUMBER(BD9),ISNUMBER($BD$6),BD9>$BD$6),"Error", IFERROR(IF(BD9="","",(BD9/$BD$6)*100),0))))))
C10: =C9+1 -> 3 | D10: 02000510545 | F10: ANDAYA,RICO BRON | G10: 100 | H10: 100 | I10: 48 | K10: =IF(OR(F10="",COUNTA(G10:J10)=0),"", IF(COUNTA(G10:J10,$G$6:$J$6)=0,"", IF(OR( AND($G$6="",G10<>""),AND(ISTEXT($G$6),$G$6<>""),AND(ISTEXT(G10),G10<>""), AND($H$6="",H10<>""),AND(ISTEXT($H$6),$H$6<>""),AND(ISTEXT(H10),H10<>""), AND($I$6="",I10<>""),AND(ISTEXT($I$6),$I$6<>""),AND(ISTEXT(I10),I10<>""), AND($J$6="",J10<>""),AND(ISTEXT($J$6),$J$6<>""),AND(ISTEXT(J10),J10<>"")),"Error", IF(OR( AND(ISNUMBER($G$6),ISNUMBER(G10),G10>$G$6), AND(ISNUMBER($H$6),ISNUMBER(H10),H10>$H$6), AND(ISNUMBER($I$6),ISNUMBER(I10),I10>$I$6), AND(ISNUMBER($J$6),ISNUMBER(J10),J10>$J$6)),"Error", IF(SUM(G10:J10)>$K$7,"Error", SUM(G10:J10)))))) -> 248 | L10: 100 | M10: 100 | N10: 100 | P10: =IF(OR(F10="",COUNTA(L10:O10)=0),"", IF(COUNTA(L10:O10,$L$6:$O$6)=0,"", IF(OR( AND($L$6="",L10<>""),AND(ISTEXT($L$6),$L$6<>""),AND(ISTEXT(L10),L10<>""), AND($M$6="",M10<>""),AND(ISTEXT($M$6),$M$6<>""),AND(ISTEXT(M10),M10<>""), AND($N$6="",N10<>""),AND(ISTEXT($N$6),$N$6<>""),AND(ISTEXT(N10),N10<>""), AND($O$6="",O10<>""),AND(ISTEXT($O$6),$O$6<>""),AND(ISTEXT(O10),O10<>"")),"Error", IF(OR( AND(ISNUMBER($L$6),ISNUMBER(L10),L10>$L$6), AND(ISNUMBER($M$6),ISNUMBER(M10),M10>$M$6), AND(ISNUMBER($N$6),ISNUMBER(N10),N10>$N$6), AND(ISNUMBER($O$6),ISNUMBER(O10),O10>$O$6)),"Error", IF(SUM(L10:O10)>$P$7,"Error", SUM(L10:O10)))))) -> 300 | Q10: 46 | R10: =IF(F10="","", IF(AND(Q10="",$Q$6=""),"", IF($Q$6="","Error", IF(OR(AND(ISTEXT(Q10),Q10<>""),AND(ISTEXT($Q$6),$Q$6<>"")),"Error", IF(AND(ISNUMBER(Q10),ISNUMBER($Q$6),Q10>$Q$6),"Error", IFERROR(IF(Q10="","",(Q10/$Q$6)*100),0)))))) -> 65.714286 | T10: 45 | U10: 50 | X10: =IF(OR(F10="",COUNTA(T10:W10)=0),"", IF(COUNTA(T10:W10,$T$6:$W$6)=0,"", IF(OR( AND($T$6="",T10<>""),AND(ISTEXT($T$6),$T$6<>""),AND(ISTEXT(T10),T10<>""), AND($U$6="",U10<>""),AND(ISTEXT($U$6),$U$6<>""),AND(ISTEXT(U10),U10<>""), AND($V$6="",V10<>""),AND(ISTEXT($V$6),$V$6<>""),AND(ISTEXT(V10),V10<>""), AND($W$6="",W10<>""),AND(ISTEXT($W$6),$W$6<>""),AND(ISTEXT(W10),W10<>"")),"Error", IF(OR( AND(ISNUMBER($T$6),ISNUMBER(T10),T10>$T$6), AND(ISNUMBER($U$6),ISNUMBER(U10),U10>$U$6), AND(ISNUMBER($V$6),ISNUMBER(V10),V10>$V$6), AND(ISNUMBER($W$6),ISNUMBER(W10),W10>$W$6)),"Error", IF(SUM(T10:W10)>$X$7,"Error", SUM(T10:W10)))))) -> 95 | Y10: 0 | Z10: 19 | AA10: 14 | AC10: =IF(OR(F10="",COUNTA(Y10:AB10)=0),"", IF(COUNTA(Y10:AB10,$Y$6:$AB$6)=0,"", IF(OR( AND($Y$6="",Y10<>""),AND(ISTEXT($Y$6),$Y$6<>""),AND(ISTEXT(Y10),Y10<>""), AND($Z$6="",Z10<>""),AND(ISTEXT($Z$6),$Z$6<>""),AND(ISTEXT(Z10),Z10<>""), AND($AA$6="",AA10<>""),AND(ISTEXT($AA$6),$AA$6<>""),AND(ISTEXT(AA10),AA10<>""), AND($AB$6="",AB10<>""),AND(ISTEXT($AB$6),$AB$6<>""),AND(ISTEXT(AB10),AB10<>"")),"Error", IF(OR( AND(ISNUMBER($Y$6),ISNUMBER(Y10),Y10>$Y$6), AND(ISNUMBER($Z$6),ISNUMBER(Z10),Z10>$Z$6), AND(ISNUMBER($AA$6),ISNUMBER(AA10),AA10>$AA$6), AND(ISNUMBER($AB$6),ISNUMBER(AB10),AB10>$AB$6)),"Error", IF(SUM(Y10:AB10)>$AC$7,"Error", SUM(Y10:AB10)))))) -> 33 | AD10: 44 | AE10: =IF(F10="","", IF(AND(AD10="",$AD$6=""),"", IF($AD$6="","Error", IF(OR(AND(ISTEXT(AD10),AD10<>""),AND(ISTEXT($AD$6),$AD$6<>"")),"Error", IF(AND(ISNUMBER(AD10),ISNUMBER($AD$6),AD10>$AD$6),"Error", IFERROR(IF(AD10="","",(AD10/$AD$6)*100),0)))))) -> 62.857143 | AK10: =IF(OR(F10="",COUNTA(AG10:AJ10)=0),"", IF(COUNTA(AG10:AJ10,$AG$6:$AJ$6)=0,"", IF(OR( AND($AG$6="",AG10<>""),AND(ISTEXT($AG$6),$AG$6<>""),AND(ISTEXT(AG10),AG10<>""), AND($AH$6="",AH10<>""),AND(ISTEXT($AH$6),$AH$6<>""),AND(ISTEXT(AH10),AH10<>""), AND($AI$6="",AI10<>""),AND(ISTEXT($AI$6),$AI$6<>""),AND(ISTEXT(AI10),AI10<>""), AND($AJ$6="",AJ10<>""),AND(ISTEXT($AJ$6),$AJ$6<>""),AND(ISTEXT(AJ10),AJ10<>"")),"Error", IF(OR( AND(ISNUMBER($AG$6),ISNUMBER(AG10),AG10>$AG$6), AND(ISNUMBER($AH$6),ISNUMBER(AH10),AH10>$AH$6), AND(ISNUMBER($AI$6),ISNUMBER(AI10),AI10>$AI$6), AND(ISNUMBER($AJ$6),ISNUMBER(AJ10),AJ10>$AJ$6)),"Error", IF(SUM(AG10:AJ10)>$AK$7,"Error", SUM(AG10:AJ10)))))) | AP10: =IF(OR(F10="",COUNTA(AL10:AO10)=0),"", IF(COUNTA(AL10:AO10,$AL$6:$AO$6)=0,"", IF(OR( AND($AL$6="",AL10<>""),AND(ISTEXT($AL$6),$AL$6<>""),AND(ISTEXT(AL10),AL10<>""), AND($AM$6="",AM10<>""),AND(ISTEXT($AM$6),$AM$6<>""),AND(ISTEXT(AM10),AM10<>""), AND($AN$6="",AN10<>""),AND(ISTEXT($AN$6),$AN$6<>""),AND(ISTEXT(AN10),AN10<>""), AND($AO$6="",AO10<>""),AND(ISTEXT($AO$6),$AO$6<>""),AND(ISTEXT(AO10),AO10<>"")),"Error", IF(OR( AND(ISNUMBER($AL$6),ISNUMBER(AL10),AL10>$AL$6), AND(ISNUMBER($AM$6),ISNUMBER(AM10),AM10>$AM$6), AND(ISNUMBER($AN$6),ISNUMBER(AN10),AN10>$AN$6), AND(ISNUMBER($AO$6),ISNUMBER(AO10),AO10>$AO$6)),"Error", IF(SUM(AL10:AO10)>$AP$7,"Error", SUM(AL10:AO10)))))) | AR10: =IF(F10="","", IF(AND(AQ10="",$AQ$6=""),"", IF($AQ$6="","Error", IF(OR(AND(ISTEXT(AQ10),AQ10<>""),AND(ISTEXT($AQ$6),$AQ$6<>"")),"Error", IF(AND(ISNUMBER(AQ10),ISNUMBER($AQ$6),AD10>$AQ$6),"Error", IFERROR(IF(AQ10="","",(AQ10/$AQ$6)*100),0)))))) | AX10: =IF(OR(F10="",COUNTA(AT10:AW10)=0),"", IF(COUNTA(AT10:AW10,$AT$6:$AW$6)=0,"", IF(OR( AND($AT$6="",AT10<>""),AND(ISTEXT($AT$6),$AT$6<>""),AND(ISTEXT(AT10),AT10<>""), AND($AU$6="",AU10<>""),AND(ISTEXT($AU$6),$AU$6<>""),AND(ISTEXT(AU10),AU10<>""), AND($AV$6="",AV10<>""),AND(ISTEXT($AV$6),$AV$6<>""),AND(ISTEXT(AV10),AV10<>""), AND($AW$6="",AW10<>""),AND(ISTEXT($AW$6),$AW$6<>""),AND(ISTEXT(AW10),AW10<>"")),"Error", IF(OR( AND(ISNUMBER($AT$6),ISNUMBER(AT10),AT10>$AT$6), AND(ISNUMBER($AU$6),ISNUMBER(AU10),AU10>$AU$6), AND(ISNUMBER($AV$6),ISNUMBER(AV10),AV10>$AV$6), AND(ISNUMBER($AW$6),ISNUMBER(AW10),AW10>$AW$6)),"Error", IF(SUM(AT10:AW10)>$AX$7,"Error", SUM(AT10:AW10)))))) | BC10: =IF(OR(F10="",COUNTA(AY10:BB10)=0),"", IF(COUNTA(AY10:BB10,$AY$6:$BB$6)=0,"", IF(OR( AND($AY$6="",AY10<>""),AND(ISTEXT($AY$6),$AY$6<>""),AND(ISTEXT(AY10),AY10<>""), AND($AZ$6="",AZ10<>""),AND(ISTEXT($AZ$6),$AZ$6<>""),AND(ISTEXT(AZ10),AZ10<>""), AND($BA$6="",BA10<>""),AND(ISTEXT($BA$6),$BA$6<>""),AND(ISTEXT(BA10),BA10<>""), AND($BB$6="",BB10<>""),AND(ISTEXT($BB$6),$BB$6<>""),AND(ISTEXT(BB10),BB10<>"")),"Error", IF(OR( AND(ISNUMBER($AY$6),ISNUMBER(AY10),AY10>$AY$6), AND(ISNUMBER($AZ$6),ISNUMBER(AZ10),AZ10>$AZ$6), AND(ISNUMBER($BA$6),ISNUMBER(BA10),BA10>$BA$6), AND(ISNUMBER($BB$6),ISNUMBER(BB10),BB10>$BB$6)),"Error", IF(SUM(AY10:BB10)>$BC$7,"Error", SUM(AY10:BB10)))))) | BE10: =IF(F10="","", IF(AND(BD10="",$BD$6=""),"", IF($BD$6="","Error", IF(OR(AND(ISTEXT(BD10),BD10<>""),AND(ISTEXT($BD$6),$BD$6<>"")),"Error", IF(AND(ISNUMBER(BD10),ISNUMBER($BD$6),BD10>$BD$6),"Error", IFERROR(IF(BD10="","",(BD10/$BD$6)*100),0))))))
C11: =C10+1 -> 4 | D11: 02000500688 | F11: AREJOLA,JESSICA SELPO | G11: 100 | H11: 100 | I11: 48 | K11: =IF(OR(F11="",COUNTA(G11:J11)=0),"", IF(COUNTA(G11:J11,$G$6:$J$6)=0,"", IF(OR( AND($G$6="",G11<>""),AND(ISTEXT($G$6),$G$6<>""),AND(ISTEXT(G11),G11<>""), AND($H$6="",H11<>""),AND(ISTEXT($H$6),$H$6<>""),AND(ISTEXT(H11),H11<>""), AND($I$6="",I11<>""),AND(ISTEXT($I$6),$I$6<>""),AND(ISTEXT(I11),I11<>""), AND($J$6="",J11<>""),AND(ISTEXT($J$6),$J$6<>""),AND(ISTEXT(J11),J11<>"")),"Error", IF(OR( AND(ISNUMBER($G$6),ISNUMBER(G11),G11>$G$6), AND(ISNUMBER($H$6),ISNUMBER(H11),H11>$H$6), AND(ISNUMBER($I$6),ISNUMBER(I11),I11>$I$6), AND(ISNUMBER($J$6),ISNUMBER(J11),J11>$J$6)),"Error", IF(SUM(G11:J11)>$K$7,"Error", SUM(G11:J11)))))) -> 248 | L11: 100 | M11: 100 | N11: 100 | P11: =IF(OR(F11="",COUNTA(L11:O11)=0),"", IF(COUNTA(L11:O11,$L$6:$O$6)=0,"", IF(OR( AND($L$6="",L11<>""),AND(ISTEXT($L$6),$L$6<>""),AND(ISTEXT(L11),L11<>""), AND($M$6="",M11<>""),AND(ISTEXT($M$6),$M$6<>""),AND(ISTEXT(M11),M11<>""), AND($N$6="",N11<>""),AND(ISTEXT($N$6),$N$6<>""),AND(ISTEXT(N11),N11<>""), AND($O$6="",O11<>""),AND(ISTEXT($O$6),$O$6<>""),AND(ISTEXT(O11),O11<>"")),"Error", IF(OR( AND(ISNUMBER($L$6),ISNUMBER(L11),L11>$L$6), AND(ISNUMBER($M$6),ISNUMBER(M11),M11>$M$6), AND(ISNUMBER($N$6),ISNUMBER(N11),N11>$N$6), AND(ISNUMBER($O$6),ISNUMBER(O11),O11>$O$6)),"Error", IF(SUM(L11:O11)>$P$7,"Error", SUM(L11:O11)))))) -> 300 | Q11: 24 | R11: =IF(F11="","", IF(AND(Q11="",$Q$6=""),"", IF($Q$6="","Error", IF(OR(AND(ISTEXT(Q11),Q11<>""),AND(ISTEXT($Q$6),$Q$6<>"")),"Error", IF(AND(ISNUMBER(Q11),ISNUMBER($Q$6),Q11>$Q$6),"Error", IFERROR(IF(Q11="","",(Q11/$Q$6)*100),0)))))) -> 34.285714 | T11: 0 | U11: 50 | X11: =IF(OR(F11="",COUNTA(T11:W11)=0),"", IF(COUNTA(T11:W11,$T$6:$W$6)=0,"", IF(OR( AND($T$6="",T11<>""),AND(ISTEXT($T$6),$T$6<>""),AND(ISTEXT(T11),T11<>""), AND($U$6="",U11<>""),AND(ISTEXT($U$6),$U$6<>""),AND(ISTEXT(U11),U11<>""), AND($V$6="",V11<>""),AND(ISTEXT($V$6),$V$6<>""),AND(ISTEXT(V11),V11<>""), AND($W$6="",W11<>""),AND(ISTEXT($W$6),$W$6<>""),AND(ISTEXT(W11),W11<>"")),"Error", IF(OR( AND(ISNUMBER($T$6),ISNUMBER(T11),T11>$T$6), AND(ISNUMBER($U$6),ISNUMBER(U11),U11>$U$6), AND(ISNUMBER($V$6),ISNUMBER(V11),V11>$V$6), AND(ISNUMBER($W$6),ISNUMBER(W11),W11>$W$6)),"Error", IF(SUM(T11:W11)>$X$7,"Error", SUM(T11:W11)))))) -> 50 | Y11: 4 | Z11: 0 | AA11: 9 | AC11: =IF(OR(F11="",COUNTA(Y11:AB11)=0),"", IF(COUNTA(Y11:AB11,$Y$6:$AB$6)=0,"", IF(OR( AND($Y$6="",Y11<>""),AND(ISTEXT($Y$6),$Y$6<>""),AND(ISTEXT(Y11),Y11<>""), AND($Z$6="",Z11<>""),AND(ISTEXT($Z$6),$Z$6<>""),AND(ISTEXT(Z11),Z11<>""), AND($AA$6="",AA11<>""),AND(ISTEXT($AA$6),$AA$6<>""),AND(ISTEXT(AA11),AA11<>""), AND($AB$6="",AB11<>""),AND(ISTEXT($AB$6),$AB$6<>""),AND(ISTEXT(AB11),AB11<>"")),"Error", IF(OR( AND(ISNUMBER($Y$6),ISNUMBER(Y11),Y11>$Y$6), AND(ISNUMBER($Z$6),ISNUMBER(Z11),Z11>$Z$6), AND(ISNUMBER($AA$6),ISNUMBER(AA11),AA11>$AA$6), AND(ISNUMBER($AB$6),ISNUMBER(AB11),AB11>$AB$6)),"Error", IF(SUM(Y11:AB11)>$AC$7,"Error", SUM(Y11:AB11)))))) -> 13 | AD11: 20 | AE11: =IF(F11="","", IF(AND(AD11="",$AD$6=""),"", IF($AD$6="","Error", IF(OR(AND(ISTEXT(AD11),AD11<>""),AND(ISTEXT($AD$6),$AD$6<>"")),"Error", IF(AND(ISNUMBER(AD11),ISNUMBER($AD$6),AD11>$AD$6),"Error", IFERROR(IF(AD11="","",(AD11/$AD$6)*100),0)))))) -> 28.571429 | AK11: =IF(OR(F11="",COUNTA(AG11:AJ11)=0),"", IF(COUNTA(AG11:AJ11,$AG$6:$AJ$6)=0,"", IF(OR( AND($AG$6="",AG11<>""),AND(ISTEXT($AG$6),$AG$6<>""),AND(ISTEXT(AG11),AG11<>""), AND($AH$6="",AH11<>""),AND(ISTEXT($AH$6),$AH$6<>""),AND(ISTEXT(AH11),AH11<>""), AND($AI$6="",AI11<>""),AND(ISTEXT($AI$6),$AI$6<>""),AND(ISTEXT(AI11),AI11<>""), AND($AJ$6="",AJ11<>""),AND(ISTEXT($AJ$6),$AJ$6<>""),AND(ISTEXT(AJ11),AJ11<>"")),"Error", IF(OR( AND(ISNUMBER($AG$6),ISNUMBER(AG11),AG11>$AG$6), AND(ISNUMBER($AH$6),ISNUMBER(AH11),AH11>$AH$6), AND(ISNUMBER($AI$6),ISNUMBER(AI11),AI11>$AI$6), AND(ISNUMBER($AJ$6),ISNUMBER(AJ11),AJ11>$AJ$6)),"Error", IF(SUM(AG11:AJ11)>$AK$7,"Error", SUM(AG11:AJ11)))))) | AP11: =IF(OR(F11="",COUNTA(AL11:AO11)=0),"", IF(COUNTA(AL11:AO11,$AL$6:$AO$6)=0,"", IF(OR( AND($AL$6="",AL11<>""),AND(ISTEXT($AL$6),$AL$6<>""),AND(ISTEXT(AL11),AL11<>""), AND($AM$6="",AM11<>""),AND(ISTEXT($AM$6),$AM$6<>""),AND(ISTEXT(AM11),AM11<>""), AND($AN$6="",AN11<>""),AND(ISTEXT($AN$6),$AN$6<>""),AND(ISTEXT(AN11),AN11<>""), AND($AO$6="",AO11<>""),AND(ISTEXT($AO$6),$AO$6<>""),AND(ISTEXT(AO11),AO11<>"")),"Error", IF(OR( AND(ISNUMBER($AL$6),ISNUMBER(AL11),AL11>$AL$6), AND(ISNUMBER($AM$6),ISNUMBER(AM11),AM11>$AM$6), AND(ISNUMBER($AN$6),ISNUMBER(AN11),AN11>$AN$6), AND(ISNUMBER($AO$6),ISNUMBER(AO11),AO11>$AO$6)),"Error", IF(SUM(AL11:AO11)>$AP$7,"Error", SUM(AL11:AO11)))))) | AR11: =IF(F11="","", IF(AND(AQ11="",$AQ$6=""),"", IF($AQ$6="","Error", IF(OR(AND(ISTEXT(AQ11),AQ11<>""),AND(ISTEXT($AQ$6),$AQ$6<>"")),"Error", IF(AND(ISNUMBER(AQ11),ISNUMBER($AQ$6),AD11>$AQ$6),"Error", IFERROR(IF(AQ11="","",(AQ11/$AQ$6)*100),0)))))) | AX11: =IF(OR(F11="",COUNTA(AT11:AW11)=0),"", IF(COUNTA(AT11:AW11,$AT$6:$AW$6)=0,"", IF(OR( AND($AT$6="",AT11<>""),AND(ISTEXT($AT$6),$AT$6<>""),AND(ISTEXT(AT11),AT11<>""), AND($AU$6="",AU11<>""),AND(ISTEXT($AU$6),$AU$6<>""),AND(ISTEXT(AU11),AU11<>""), AND($AV$6="",AV11<>""),AND(ISTEXT($AV$6),$AV$6<>""),AND(ISTEXT(AV11),AV11<>""), AND($AW$6="",AW11<>""),AND(ISTEXT($AW$6),$AW$6<>""),AND(ISTEXT(AW11),AW11<>"")),"Error", IF(OR( AND(ISNUMBER($AT$6),ISNUMBER(AT11),AT11>$AT$6), AND(ISNUMBER($AU$6),ISNUMBER(AU11),AU11>$AU$6), AND(ISNUMBER($AV$6),ISNUMBER(AV11),AV11>$AV$6), AND(ISNUMBER($AW$6),ISNUMBER(AW11),AW11>$AW$6)),"Error", IF(SUM(AT11:AW11)>$AX$7,"Error", SUM(AT11:AW11)))))) | BC11: =IF(OR(F11="",COUNTA(AY11:BB11)=0),"", IF(COUNTA(AY11:BB11,$AY$6:$BB$6)=0,"", IF(OR( AND($AY$6="",AY11<>""),AND(ISTEXT($AY$6),$AY$6<>""),AND(ISTEXT(AY11),AY11<>""), AND($AZ$6="",AZ11<>""),AND(ISTEXT($AZ$6),$AZ$6<>""),AND(ISTEXT(AZ11),AZ11<>""), AND($BA$6="",BA11<>""),AND(ISTEXT($BA$6),$BA$6<>""),AND(ISTEXT(BA11),BA11<>""), AND($BB$6="",BB11<>""),AND(ISTEXT($BB$6),$BB$6<>""),AND(ISTEXT(BB11),BB11<>"")),"Error", IF(OR( AND(ISNUMBER($AY$6),ISNUMBER(AY11),AY11>$AY$6), AND(ISNUMBER($AZ$6),ISNUMBER(AZ11),AZ11>$AZ$6), AND(ISNUMBER($BA$6),ISNUMBER(BA11),BA11>$BA$6), AND(ISNUMBER($BB$6),ISNUMBER(BB11),BB11>$BB$6)),"Error", IF(SUM(AY11:BB11)>$BC$7,"Error", SUM(AY11:BB11)))))) | BE11: =IF(F11="","", IF(AND(BD11="",$BD$6=""),"", IF($BD$6="","Error", IF(OR(AND(ISTEXT(BD11),BD11<>""),AND(ISTEXT($BD$6),$BD$6<>"")),"Error", IF(AND(ISNUMBER(BD11),ISNUMBER($BD$6),BD11>$BD$6),"Error", IFERROR(IF(BD11="","",(BD11/$BD$6)*100),0))))))
C12: =C11+1 -> 5 | D12: 02000491309 | F12: BAGAMASBAD,KYLA ANGELICA | G12: 100 | H12: 100 | I12: 48 | K12: =IF(OR(F12="",COUNTA(G12:J12)=0),"", IF(COUNTA(G12:J12,$G$6:$J$6)=0,"", IF(OR( AND($G$6="",G12<>""),AND(ISTEXT($G$6),$G$6<>""),AND(ISTEXT(G12),G12<>""), AND($H$6="",H12<>""),AND(ISTEXT($H$6),$H$6<>""),AND(ISTEXT(H12),H12<>""), AND($I$6="",I12<>""),AND(ISTEXT($I$6),$I$6<>""),AND(ISTEXT(I12),I12<>""), AND($J$6="",J12<>""),AND(ISTEXT($J$6),$J$6<>""),AND(ISTEXT(J12),J12<>"")),"Error", IF(OR( AND(ISNUMBER($G$6),ISNUMBER(G12),G12>$G$6), AND(ISNUMBER($H$6),ISNUMBER(H12),H12>$H$6), AND(ISNUMBER($I$6),ISNUMBER(I12),I12>$I$6), AND(ISNUMBER($J$6),ISNUMBER(J12),J12>$J$6)),"Error", IF(SUM(G12:J12)>$K$7,"Error", SUM(G12:J12)))))) -> 248 | L12: 100 | M12: 100 | N12: 100 | P12: =IF(OR(F12="",COUNTA(L12:O12)=0),"", IF(COUNTA(L12:O12,$L$6:$O$6)=0,"", IF(OR( AND($L$6="",L12<>""),AND(ISTEXT($L$6),$L$6<>""),AND(ISTEXT(L12),L12<>""), AND($M$6="",M12<>""),AND(ISTEXT($M$6),$M$6<>""),AND(ISTEXT(M12),M12<>""), AND($N$6="",N12<>""),AND(ISTEXT($N$6),$N$6<>""),AND(ISTEXT(N12),N12<>""), AND($O$6="",O12<>""),AND(ISTEXT($O$6),$O$6<>""),AND(ISTEXT(O12),O12<>"")),"Error", IF(OR( AND(ISNUMBER($L$6),ISNUMBER(L12),L12>$L$6), AND(ISNUMBER($M$6),ISNUMBER(M12),M12>$M$6), AND(ISNUMBER($N$6),ISNUMBER(N12),N12>$N$6), AND(ISNUMBER($O$6),ISNUMBER(O12),O12>$O$6)),"Error", IF(SUM(L12:O12)>$P$7,"Error", SUM(L12:O12)))))) -> 300 | Q12: 54 | R12: =IF(F12="","", IF(AND(Q12="",$Q$6=""),"", IF($Q$6="","Error", IF(OR(AND(ISTEXT(Q12),Q12<>""),AND(ISTEXT($Q$6),$Q$6<>"")),"Error", IF(AND(ISNUMBER(Q12),ISNUMBER($Q$6),Q12>$Q$6),"Error", IFERROR(IF(Q12="","",(Q12/$Q$6)*100),0)))))) -> 77.142857 | T12: 43 | U12: 50 | X12: =IF(OR(F12="",COUNTA(T12:W12)=0),"", IF(COUNTA(T12:W12,$T$6:$W$6)=0,"", IF(OR( AND($T$6="",T12<>""),AND(ISTEXT($T$6),$T$6<>""),AND(ISTEXT(T12),T12<>""), AND($U$6="",U12<>""),AND(ISTEXT($U$6),$U$6<>""),AND(ISTEXT(U12),U12<>""), AND($V$6="",V12<>""),AND(ISTEXT($V$6),$V$6<>""),AND(ISTEXT(V12),V12<>""), AND($W$6="",W12<>""),AND(ISTEXT($W$6),$W$6<>""),AND(ISTEXT(W12),W12<>"")),"Error", IF(OR( AND(ISNUMBER($T$6),ISNUMBER(T12),T12>$T$6), AND(ISNUMBER($U$6),ISNUMBER(U12),U12>$U$6), AND(ISNUMBER($V$6),ISNUMBER(V12),V12>$V$6), AND(ISNUMBER($W$6),ISNUMBER(W12),W12>$W$6)),"Error", IF(SUM(T12:W12)>$X$7,"Error", SUM(T12:W12)))))) -> 93 | Y12: 0 | Z12: 20 | AA12: 17 | AC12: =IF(OR(F12="",COUNTA(Y12:AB12)=0),"", IF(COUNTA(Y12:AB12,$Y$6:$AB$6)=0,"", IF(OR( AND($Y$6="",Y12<>""),AND(ISTEXT($Y$6),$Y$6<>""),AND(ISTEXT(Y12),Y12<>""), AND($Z$6="",Z12<>""),AND(ISTEXT($Z$6),$Z$6<>""),AND(ISTEXT(Z12),Z12<>""), AND($AA$6="",AA12<>""),AND(ISTEXT($AA$6),$AA$6<>""),AND(ISTEXT(AA12),AA12<>""), AND($AB$6="",AB12<>""),AND(ISTEXT($AB$6),$AB$6<>""),AND(ISTEXT(AB12),AB12<>"")),"Error", IF(OR( AND(ISNUMBER($Y$6),ISNUMBER(Y12),Y12>$Y$6), AND(ISNUMBER($Z$6),ISNUMBER(Z12),Z12>$Z$6), AND(ISNUMBER($AA$6),ISNUMBER(AA12),AA12>$AA$6), AND(ISNUMBER($AB$6),ISNUMBER(AB12),AB12>$AB$6)),"Error", IF(SUM(Y12:AB12)>$AC$7,"Error", SUM(Y12:AB12)))))) -> 37 | AD12: 44 | AE12: =IF(F12="","", IF(AND(AD12="",$AD$6=""),"", IF($AD$6="","Error", IF(OR(AND(ISTEXT(AD12),AD12<>""),AND(ISTEXT($AD$6),$AD$6<>"")),"Error", IF(AND(ISNUMBER(AD12),ISNUMBER($AD$6),AD12>$AD$6),"Error", IFERROR(IF(AD12="","",(AD12/$AD$6)*100),0)))))) -> 62.857143 | AK12: =IF(OR(F12="",COUNTA(AG12:AJ12)=0),"", IF(COUNTA(AG12:AJ12,$AG$6:$AJ$6)=0,"", IF(OR( AND($AG$6="",AG12<>""),AND(ISTEXT($AG$6),$AG$6<>""),AND(ISTEXT(AG12),AG12<>""), AND($AH$6="",AH12<>""),AND(ISTEXT($AH$6),$AH$6<>""),AND(ISTEXT(AH12),AH12<>""), AND($AI$6="",AI12<>""),AND(ISTEXT($AI$6),$AI$6<>""),AND(ISTEXT(AI12),AI12<>""), AND($AJ$6="",AJ12<>""),AND(ISTEXT($AJ$6),$AJ$6<>""),AND(ISTEXT(AJ12),AJ12<>"")),"Error", IF(OR( AND(ISNUMBER($AG$6),ISNUMBER(AG12),AG12>$AG$6), AND(ISNUMBER($AH$6),ISNUMBER(AH12),AH12>$AH$6), AND(ISNUMBER($AI$6),ISNUMBER(AI12),AI12>$AI$6), AND(ISNUMBER($AJ$6),ISNUMBER(AJ12),AJ12>$AJ$6)),"Error", IF(SUM(AG12:AJ12)>$AK$7,"Error", SUM(AG12:AJ12)))))) | AP12: =IF(OR(F12="",COUNTA(AL12:AO12)=0),"", IF(COUNTA(AL12:AO12,$AL$6:$AO$6)=0,"", IF(OR( AND($AL$6="",AL12<>""),AND(ISTEXT($AL$6),$AL$6<>""),AND(ISTEXT(AL12),AL12<>""), AND($AM$6="",AM12<>""),AND(ISTEXT($AM$6),$AM$6<>""),AND(ISTEXT(AM12),AM12<>""), AND($AN$6="",AN12<>""),AND(ISTEXT($AN$6),$AN$6<>""),AND(ISTEXT(AN12),AN12<>""), AND($AO$6="",AO12<>""),AND(ISTEXT($AO$6),$AO$6<>""),AND(ISTEXT(AO12),AO12<>"")),"Error", IF(OR( AND(ISNUMBER($AL$6),ISNUMBER(AL12),AL12>$AL$6), AND(ISNUMBER($AM$6),ISNUMBER(AM12),AM12>$AM$6), AND(ISNUMBER($AN$6),ISNUMBER(AN12),AN12>$AN$6), AND(ISNUMBER($AO$6),ISNUMBER(AO12),AO12>$AO$6)),"Error", IF(SUM(AL12:AO12)>$AP$7,"Error", SUM(AL12:AO12)))))) | AR12: =IF(F12="","", IF(AND(AQ12="",$AQ$6=""),"", IF($AQ$6="","Error", IF(OR(AND(ISTEXT(AQ12),AQ12<>""),AND(ISTEXT($AQ$6),$AQ$6<>"")),"Error", IF(AND(ISNUMBER(AQ12),ISNUMBER($AQ$6),AD12>$AQ$6),"Error", IFERROR(IF(AQ12="","",(AQ12/$AQ$6)*100),0)))))) | AX12: =IF(OR(F12="",COUNTA(AT12:AW12)=0),"", IF(COUNTA(AT12:AW12,$AT$6:$AW$6)=0,"", IF(OR( AND($AT$6="",AT12<>""),AND(ISTEXT($AT$6),$AT$6<>""),AND(ISTEXT(AT12),AT12<>""), AND($AU$6="",AU12<>""),AND(ISTEXT($AU$6),$AU$6<>""),AND(ISTEXT(AU12),AU12<>""), AND($AV$6="",AV12<>""),AND(ISTEXT($AV$6),$AV$6<>""),AND(ISTEXT(AV12),AV12<>""), AND($AW$6="",AW12<>""),AND(ISTEXT($AW$6),$AW$6<>""),AND(ISTEXT(AW12),AW12<>"")),"Error", IF(OR( AND(ISNUMBER($AT$6),ISNUMBER(AT12),AT12>$AT$6), AND(ISNUMBER($AU$6),ISNUMBER(AU12),AU12>$AU$6), AND(ISNUMBER($AV$6),ISNUMBER(AV12),AV12>$AV$6), AND(ISNUMBER($AW$6),ISNUMBER(AW12),AW12>$AW$6)),"Error", IF(SUM(AT12:AW12)>$AX$7,"Error", SUM(AT12:AW12)))))) | BC12: =IF(OR(F12="",COUNTA(AY12:BB12)=0),"", IF(COUNTA(AY12:BB12,$AY$6:$BB$6)=0,"", IF(OR( AND($AY$6="",AY12<>""),AND(ISTEXT($AY$6),$AY$6<>""),AND(ISTEXT(AY12),AY12<>""), AND($AZ$6="",AZ12<>""),AND(ISTEXT($AZ$6),$AZ$6<>""),AND(ISTEXT(AZ12),AZ12<>""), AND($BA$6="",BA12<>""),AND(ISTEXT($BA$6),$BA$6<>""),AND(ISTEXT(BA12),BA12<>""), AND($BB$6="",BB12<>""),AND(ISTEXT($BB$6),$BB$6<>""),AND(ISTEXT(BB12),BB12<>"")),"Error", IF(OR( AND(ISNUMBER($AY$6),ISNUMBER(AY12),AY12>$AY$6), AND(ISNUMBER($AZ$6),ISNUMBER(AZ12),AZ12>$AZ$6), AND(ISNUMBER($BA$6),ISNUMBER(BA12),BA12>$BA$6), AND(ISNUMBER($BB$6),ISNUMBER(BB12),BB12>$BB$6)),"Error", IF(SUM(AY12:BB12)>$BC$7,"Error", SUM(AY12:BB12)))))) | BE12: =IF(F12="","", IF(AND(BD12="",$BD$6=""),"", IF($BD$6="","Error", IF(OR(AND(ISTEXT(BD12),BD12<>""),AND(ISTEXT($BD$6),$BD$6<>"")),"Error", IF(AND(ISNUMBER(BD12),ISNUMBER($BD$6),BD12>$BD$6),"Error", IFERROR(IF(BD12="","",(BD12/$BD$6)*100),0))))))
C13: =C12+1 -> 6 | D13: 02000496750 | F13: BALTE,LYZA MAE LOMA | G13: 90 | H13: 90 | I13: 47 | K13: =IF(OR(F13="",COUNTA(G13:J13)=0),"", IF(COUNTA(G13:J13,$G$6:$J$6)=0,"", IF(OR( AND($G$6="",G13<>""),AND(ISTEXT($G$6),$G$6<>""),AND(ISTEXT(G13),G13<>""), AND($H$6="",H13<>""),AND(ISTEXT($H$6),$H$6<>""),AND(ISTEXT(H13),H13<>""), AND($I$6="",I13<>""),AND(ISTEXT($I$6),$I$6<>""),AND(ISTEXT(I13),I13<>""), AND($J$6="",J13<>""),AND(ISTEXT($J$6),$J$6<>""),AND(ISTEXT(J13),J13<>"")),"Error", IF(OR( AND(ISNUMBER($G$6),ISNUMBER(G13),G13>$G$6), AND(ISNUMBER($H$6),ISNUMBER(H13),H13>$H$6), AND(ISNUMBER($I$6),ISNUMBER(I13),I13>$I$6), AND(ISNUMBER($J$6),ISNUMBER(J13),J13>$J$6)),"Error", IF(SUM(G13:J13)>$K$7,"Error", SUM(G13:J13)))))) -> 227 | L13: 98 | M13: 98 | N13: 98 | P13: =IF(OR(F13="",COUNTA(L13:O13)=0),"", IF(COUNTA(L13:O13,$L$6:$O$6)=0,"", IF(OR( AND($L$6="",L13<>""),AND(ISTEXT($L$6),$L$6<>""),AND(ISTEXT(L13),L13<>""), AND($M$6="",M13<>""),AND(ISTEXT($M$6),$M$6<>""),AND(ISTEXT(M13),M13<>""), AND($N$6="",N13<>""),AND(ISTEXT($N$6),$N$6<>""),AND(ISTEXT(N13),N13<>""), AND($O$6="",O13<>""),AND(ISTEXT($O$6),$O$6<>""),AND(ISTEXT(O13),O13<>"")),"Error", IF(OR( AND(ISNUMBER($L$6),ISNUMBER(L13),L13>$L$6), AND(ISNUMBER($M$6),ISNUMBER(M13),M13>$M$6), AND(ISNUMBER($N$6),ISNUMBER(N13),N13>$N$6), AND(ISNUMBER($O$6),ISNUMBER(O13),O13>$O$6)),"Error", IF(SUM(L13:O13)>$P$7,"Error", SUM(L13:O13)))))) -> 294 | Q13: 64 | R13: =IF(F13="","", IF(AND(Q13="",$Q$6=""),"", IF($Q$6="","Error", IF(OR(AND(ISTEXT(Q13),Q13<>""),AND(ISTEXT($Q$6),$Q$6<>"")),"Error", IF(AND(ISNUMBER(Q13),ISNUMBER($Q$6),Q13>$Q$6),"Error", IFERROR(IF(Q13="","",(Q13/$Q$6)*100),0)))))) -> 91.428571 | T13: 50 | U13: 50 | X13: =IF(OR(F13="",COUNTA(T13:W13)=0),"", IF(COUNTA(T13:W13,$T$6:$W$6)=0,"", IF(OR( AND($T$6="",T13<>""),AND(ISTEXT($T$6),$T$6<>""),AND(ISTEXT(T13),T13<>""), AND($U$6="",U13<>""),AND(ISTEXT($U$6),$U$6<>""),AND(ISTEXT(U13),U13<>""), AND($V$6="",V13<>""),AND(ISTEXT($V$6),$V$6<>""),AND(ISTEXT(V13),V13<>""), AND($W$6="",W13<>""),AND(ISTEXT($W$6),$W$6<>""),AND(ISTEXT(W13),W13<>"")),"Error", IF(OR( AND(ISNUMBER($T$6),ISNUMBER(T13),T13>$T$6), AND(ISNUMBER($U$6),ISNUMBER(U13),U13>$U$6), AND(ISNUMBER($V$6),ISNUMBER(V13),V13>$V$6), AND(ISNUMBER($W$6),ISNUMBER(W13),W13>$W$6)),"Error", IF(SUM(T13:W13)>$X$7,"Error", SUM(T13:W13)))))) -> 100 | Y13: 2 | Z13: 8 | AA13: 17 | AC13: =IF(OR(F13="",COUNTA(Y13:AB13)=0),"", IF(COUNTA(Y13:AB13,$Y$6:$AB$6)=0,"", IF(OR( AND($Y$6="",Y13<>""),AND(ISTEXT($Y$6),$Y$6<>""),AND(ISTEXT(Y13),Y13<>""), AND($Z$6="",Z13<>""),AND(ISTEXT($Z$6),$Z$6<>""),AND(ISTEXT(Z13),Z13<>""), AND($AA$6="",AA13<>""),AND(ISTEXT($AA$6),$AA$6<>""),AND(ISTEXT(AA13),AA13<>""), AND($AB$6="",AB13<>""),AND(ISTEXT($AB$6),$AB$6<>""),AND(ISTEXT(AB13),AB13<>"")),"Error", IF(OR( AND(ISNUMBER($Y$6),ISNUMBER(Y13),Y13>$Y$6), AND(ISNUMBER($Z$6),ISNUMBER(Z13),Z13>$Z$6), AND(ISNUMBER($AA$6),ISNUMBER(AA13),AA13>$AA$6), AND(ISNUMBER($AB$6),ISNUMBER(AB13),AB13>$AB$6)),"Error", IF(SUM(Y13:AB13)>$AC$7,"Error", SUM(Y13:AB13)))))) -> 27 | AD13: 44 | AE13: =IF(F13="","", IF(AND(AD13="",$AD$6=""),"", IF($AD$6="","Error", IF(OR(AND(ISTEXT(AD13),AD13<>""),AND(ISTEXT($AD$6),$AD$6<>"")),"Error", IF(AND(ISNUMBER(AD13),ISNUMBER($AD$6),AD13>$AD$6),"Error", IFERROR(IF(AD13="","",(AD13/$AD$6)*100),0)))))) -> 62.857143 | AK13: =IF(OR(F13="",COUNTA(AG13:AJ13)=0),"", IF(COUNTA(AG13:AJ13,$AG$6:$AJ$6)=0,"", IF(OR( AND($AG$6="",AG13<>""),AND(ISTEXT($AG$6),$AG$6<>""),AND(ISTEXT(AG13),AG13<>""), AND($AH$6="",AH13<>""),AND(ISTEXT($AH$6),$AH$6<>""),AND(ISTEXT(AH13),AH13<>""), AND($AI$6="",AI13<>""),AND(ISTEXT($AI$6),$AI$6<>""),AND(ISTEXT(AI13),AI13<>""), AND($AJ$6="",AJ13<>""),AND(ISTEXT($AJ$6),$AJ$6<>""),AND(ISTEXT(AJ13),AJ13<>"")),"Error", IF(OR( AND(ISNUMBER($AG$6),ISNUMBER(AG13),AG13>$AG$6), AND(ISNUMBER($AH$6),ISNUMBER(AH13),AH13>$AH$6), AND(ISNUMBER($AI$6),ISNUMBER(AI13),AI13>$AI$6), AND(ISNUMBER($AJ$6),ISNUMBER(AJ13),AJ13>$AJ$6)),"Error", IF(SUM(AG13:AJ13)>$AK$7,"Error", SUM(AG13:AJ13)))))) | AP13: =IF(OR(F13="",COUNTA(AL13:AO13)=0),"", IF(COUNTA(AL13:AO13,$AL$6:$AO$6)=0,"", IF(OR( AND($AL$6="",AL13<>""),AND(ISTEXT($AL$6),$AL$6<>""),AND(ISTEXT(AL13),AL13<>""), AND($AM$6="",AM13<>""),AND(ISTEXT($AM$6),$AM$6<>""),AND(ISTEXT(AM13),AM13<>""), AND($AN$6="",AN13<>""),AND(ISTEXT($AN$6),$AN$6<>""),AND(ISTEXT(AN13),AN13<>""), AND($AO$6="",AO13<>""),AND(ISTEXT($AO$6),$AO$6<>""),AND(ISTEXT(AO13),AO13<>"")),"Error", IF(OR( AND(ISNUMBER($AL$6),ISNUMBER(AL13),AL13>$AL$6), AND(ISNUMBER($AM$6),ISNUMBER(AM13),AM13>$AM$6), AND(ISNUMBER($AN$6),ISNUMBER(AN13),AN13>$AN$6), AND(ISNUMBER($AO$6),ISNUMBER(AO13),AO13>$AO$6)),"Error", IF(SUM(AL13:AO13)>$AP$7,"Error", SUM(AL13:AO13)))))) | AR13: =IF(F13="","", IF(AND(AQ13="",$AQ$6=""),"", IF($AQ$6="","Error", IF(OR(AND(ISTEXT(AQ13),AQ13<>""),AND(ISTEXT($AQ$6),$AQ$6<>"")),"Error", IF(AND(ISNUMBER(AQ13),ISNUMBER($AQ$6),AD13>$AQ$6),"Error", IFERROR(IF(AQ13="","",(AQ13/$AQ$6)*100),0)))))) | AX13: =IF(OR(F13="",COUNTA(AT13:AW13)=0),"", IF(COUNTA(AT13:AW13,$AT$6:$AW$6)=0,"", IF(OR( AND($AT$6="",AT13<>""),AND(ISTEXT($AT$6),$AT$6<>""),AND(ISTEXT(AT13),AT13<>""), AND($AU$6="",AU13<>""),AND(ISTEXT($AU$6),$AU$6<>""),AND(ISTEXT(AU13),AU13<>""), AND($AV$6="",AV13<>""),AND(ISTEXT($AV$6),$AV$6<>""),AND(ISTEXT(AV13),AV13<>""), AND($AW$6="",AW13<>""),AND(ISTEXT($AW$6),$AW$6<>""),AND(ISTEXT(AW13),AW13<>"")),"Error", IF(OR( AND(ISNUMBER($AT$6),ISNUMBER(AT13),AT13>$AT$6), AND(ISNUMBER($AU$6),ISNUMBER(AU13),AU13>$AU$6), AND(ISNUMBER($AV$6),ISNUMBER(AV13),AV13>$AV$6), AND(ISNUMBER($AW$6),ISNUMBER(AW13),AW13>$AW$6)),"Error", IF(SUM(AT13:AW13)>$AX$7,"Error", SUM(AT13:AW13)))))) | BC13: =IF(OR(F13="",COUNTA(AY13:BB13)=0),"", IF(COUNTA(AY13:BB13,$AY$6:$BB$6)=0,"", IF(OR( AND($AY$6="",AY13<>""),AND(ISTEXT($AY$6),$AY$6<>""),AND(ISTEXT(AY13),AY13<>""), AND($AZ$6="",AZ13<>""),AND(ISTEXT($AZ$6),$AZ$6<>""),AND(ISTEXT(AZ13),AZ13<>""), AND($BA$6="",BA13<>""),AND(ISTEXT($BA$6),$BA$6<>""),AND(ISTEXT(BA13),BA13<>""), AND($BB$6="",BB13<>""),AND(ISTEXT($BB$6),$BB$6<>""),AND(ISTEXT(BB13),BB13<>"")),"Error", IF(OR( AND(ISNUMBER($AY$6),ISNUMBER(AY13),AY13>$AY$6), AND(ISNUMBER($AZ$6),ISNUMBER(AZ13),AZ13>$AZ$6), AND(ISNUMBER($BA$6),ISNUMBER(BA13),BA13>$BA$6), AND(ISNUMBER($BB$6),ISNUMBER(BB13),BB13>$BB$6)),"Error", IF(SUM(AY13:BB13)>$BC$7,"Error", SUM(AY13:BB13)))))) | BE13: =IF(F13="","", IF(AND(BD13="",$BD$6=""),"", IF($BD$6="","Error", IF(OR(AND(ISTEXT(BD13),BD13<>""),AND(ISTEXT($BD$6),$BD$6<>"")),"Error", IF(AND(ISNUMBER(BD13),ISNUMBER($BD$6),BD13>$BD$6),"Error", IFERROR(IF(BD13="","",(BD13/$BD$6)*100),0))))))
C14: =C13+1 -> 7 | D14: 02000486779 | F14: BUENAAGUA,AIRA ALANA AMPARADO | G14: 100 | H14: 100 | I14: 48 | K14: =IF(OR(F14="",COUNTA(G14:J14)=0),"", IF(COUNTA(G14:J14,$G$6:$J$6)=0,"", IF(OR( AND($G$6="",G14<>""),AND(ISTEXT($G$6),$G$6<>""),AND(ISTEXT(G14),G14<>""), AND($H$6="",H14<>""),AND(ISTEXT($H$6),$H$6<>""),AND(ISTEXT(H14),H14<>""), AND($I$6="",I14<>""),AND(ISTEXT($I$6),$I$6<>""),AND(ISTEXT(I14),I14<>""), AND($J$6="",J14<>""),AND(ISTEXT($J$6),$J$6<>""),AND(ISTEXT(J14),J14<>"")),"Error", IF(OR( AND(ISNUMBER($G$6),ISNUMBER(G14),G14>$G$6), AND(ISNUMBER($H$6),ISNUMBER(H14),H14>$H$6), AND(ISNUMBER($I$6),ISNUMBER(I14),I14>$I$6), AND(ISNUMBER($J$6),ISNUMBER(J14),J14>$J$6)),"Error", IF(SUM(G14:J14)>$K$7,"Error", SUM(G14:J14)))))) -> 248 | L14: 100 | M14: 100 | N14: 100 | P14: =IF(OR(F14="",COUNTA(L14:O14)=0),"", IF(COUNTA(L14:O14,$L$6:$O$6)=0,"", IF(OR( AND($L$6="",L14<>""),AND(ISTEXT($L$6),$L$6<>""),AND(ISTEXT(L14),L14<>""), AND($M$6="",M14<>""),AND(ISTEXT($M$6),$M$6<>""),AND(ISTEXT(M14),M14<>""), AND($N$6="",N14<>""),AND(ISTEXT($N$6),$N$6<>""),AND(ISTEXT(N14),N14<>""), AND($O$6="",O14<>""),AND(ISTEXT($O$6),$O$6<>""),AND(ISTEXT(O14),O14<>"")),"Error", IF(OR( AND(ISNUMBER($L$6),ISNUMBER(L14),L14>$L$6), AND(ISNUMBER($M$6),ISNUMBER(M14),M14>$M$6), AND(ISNUMBER($N$6),ISNUMBER(N14),N14>$N$6), AND(ISNUMBER($O$6),ISNUMBER(O14),O14>$O$6)),"Error", IF(SUM(L14:O14)>$P$7,"Error", SUM(L14:O14)))))) -> 300 | Q14: 48 | R14: =IF(F14="","", IF(AND(Q14="",$Q$6=""),"", IF($Q$6="","Error", IF(OR(AND(ISTEXT(Q14),Q14<>""),AND(ISTEXT($Q$6),$Q$6<>"")),"Error", IF(AND(ISNUMBER(Q14),ISNUMBER($Q$6),Q14>$Q$6),"Error", IFERROR(IF(Q14="","",(Q14/$Q$6)*100),0)))))) -> 68.571429 | T14: 45 | U14: 50 | X14: =IF(OR(F14="",COUNTA(T14:W14)=0),"", IF(COUNTA(T14:W14,$T$6:$W$6)=0,"", IF(OR( AND($T$6="",T14<>""),AND(ISTEXT($T$6),$T$6<>""),AND(ISTEXT(T14),T14<>""), AND($U$6="",U14<>""),AND(ISTEXT($U$6),$U$6<>""),AND(ISTEXT(U14),U14<>""), AND($V$6="",V14<>""),AND(ISTEXT($V$6),$V$6<>""),AND(ISTEXT(V14),V14<>""), AND($W$6="",W14<>""),AND(ISTEXT($W$6),$W$6<>""),AND(ISTEXT(W14),W14<>"")),"Error", IF(OR( AND(ISNUMBER($T$6),ISNUMBER(T14),T14>$T$6), AND(ISNUMBER($U$6),ISNUMBER(U14),U14>$U$6), AND(ISNUMBER($V$6),ISNUMBER(V14),V14>$V$6), AND(ISNUMBER($W$6),ISNUMBER(W14),W14>$W$6)),"Error", IF(SUM(T14:W14)>$X$7,"Error", SUM(T14:W14)))))) -> 95 | Y14: 10 | Z14: 0 | AA14: 16 | AC14: =IF(OR(F14="",COUNTA(Y14:AB14)=0),"", IF(COUNTA(Y14:AB14,$Y$6:$AB$6)=0,"", IF(OR( AND($Y$6="",Y14<>""),AND(ISTEXT($Y$6),$Y$6<>""),AND(ISTEXT(Y14),Y14<>""), AND($Z$6="",Z14<>""),AND(ISTEXT($Z$6),$Z$6<>""),AND(ISTEXT(Z14),Z14<>""), AND($AA$6="",AA14<>""),AND(ISTEXT($AA$6),$AA$6<>""),AND(ISTEXT(AA14),AA14<>""), AND($AB$6="",AB14<>""),AND(ISTEXT($AB$6),$AB$6<>""),AND(ISTEXT(AB14),AB14<>"")),"Error", IF(OR( AND(ISNUMBER($Y$6),ISNUMBER(Y14),Y14>$Y$6), AND(ISNUMBER($Z$6),ISNUMBER(Z14),Z14>$Z$6), AND(ISNUMBER($AA$6),ISNUMBER(AA14),AA14>$AA$6), AND(ISNUMBER($AB$6),ISNUMBER(AB14),AB14>$AB$6)),"Error", IF(SUM(Y14:AB14)>$AC$7,"Error", SUM(Y14:AB14)))))) -> 26 | AD14: 28 | AE14: =IF(F14="","", IF(AND(AD14="",$AD$6=""),"", IF($AD$6="","Error", IF(OR(AND(ISTEXT(AD14),AD14<>""),AND(ISTEXT($AD$6),$AD$6<>"")),"Error", IF(AND(ISNUMBER(AD14),ISNUMBER($AD$6),AD14>$AD$6),"Error", IFERROR(IF(AD14="","",(AD14/$AD$6)*100),0)))))) -> 40 | AK14: =IF(OR(F14="",COUNTA(AG14:AJ14)=0),"", IF(COUNTA(AG14:AJ14,$AG$6:$AJ$6)=0,"", IF(OR( AND($AG$6="",AG14<>""),AND(ISTEXT($AG$6),$AG$6<>""),AND(ISTEXT(AG14),AG14<>""), AND($AH$6="",AH14<>""),AND(ISTEXT($AH$6),$AH$6<>""),AND(ISTEXT(AH14),AH14<>""), AND($AI$6="",AI14<>""),AND(ISTEXT($AI$6),$AI$6<>""),AND(ISTEXT(AI14),AI14<>""), AND($AJ$6="",AJ14<>""),AND(ISTEXT($AJ$6),$AJ$6<>""),AND(ISTEXT(AJ14),AJ14<>"")),"Error", IF(OR( AND(ISNUMBER($AG$6),ISNUMBER(AG14),AG14>$AG$6), AND(ISNUMBER($AH$6),ISNUMBER(AH14),AH14>$AH$6), AND(ISNUMBER($AI$6),ISNUMBER(AI14),AI14>$AI$6), AND(ISNUMBER($AJ$6),ISNUMBER(AJ14),AJ14>$AJ$6)),"Error", IF(SUM(AG14:AJ14)>$AK$7,"Error", SUM(AG14:AJ14)))))) | AP14: =IF(OR(F14="",COUNTA(AL14:AO14)=0),"", IF(COUNTA(AL14:AO14,$AL$6:$AO$6)=0,"", IF(OR( AND($AL$6="",AL14<>""),AND(ISTEXT($AL$6),$AL$6<>""),AND(ISTEXT(AL14),AL14<>""), AND($AM$6="",AM14<>""),AND(ISTEXT($AM$6),$AM$6<>""),AND(ISTEXT(AM14),AM14<>""), AND($AN$6="",AN14<>""),AND(ISTEXT($AN$6),$AN$6<>""),AND(ISTEXT(AN14),AN14<>""), AND($AO$6="",AO14<>""),AND(ISTEXT($AO$6),$AO$6<>""),AND(ISTEXT(AO14),AO14<>"")),"Error", IF(OR( AND(ISNUMBER($AL$6),ISNUMBER(AL14),AL14>$AL$6), AND(ISNUMBER($AM$6),ISNUMBER(AM14),AM14>$AM$6), AND(ISNUMBER($AN$6),ISNUMBER(AN14),AN14>$AN$6), AND(ISNUMBER($AO$6),ISNUMBER(AO14),AO14>$AO$6)),"Error", IF(SUM(AL14:AO14)>$AP$7,"Error", SUM(AL14:AO14)))))) | AR14: =IF(F14="","", IF(AND(AQ14="",$AQ$6=""),"", IF($AQ$6="","Error", IF(OR(AND(ISTEXT(AQ14),AQ14<>""),AND(ISTEXT($AQ$6),$AQ$6<>"")),"Error", IF(AND(ISNUMBER(AQ14),ISNUMBER($AQ$6),AD14>$AQ$6),"Error", IFERROR(IF(AQ14="","",(AQ14/$AQ$6)*100),0)))))) | AX14: =IF(OR(F14="",COUNTA(AT14:AW14)=0),"", IF(COUNTA(AT14:AW14,$AT$6:$AW$6)=0,"", IF(OR( AND($AT$6="",AT14<>""),AND(ISTEXT($AT$6),$AT$6<>""),AND(ISTEXT(AT14),AT14<>""), AND($AU$6="",AU14<>""),AND(ISTEXT($AU$6),$AU$6<>""),AND(ISTEXT(AU14),AU14<>""), AND($AV$6="",AV14<>""),AND(ISTEXT($AV$6),$AV$6<>""),AND(ISTEXT(AV14),AV14<>""), AND($AW$6="",AW14<>""),AND(ISTEXT($AW$6),$AW$6<>""),AND(ISTEXT(AW14),AW14<>"")),"Error", IF(OR( AND(ISNUMBER($AT$6),ISNUMBER(AT14),AT14>$AT$6), AND(ISNUMBER($AU$6),ISNUMBER(AU14),AU14>$AU$6), AND(ISNUMBER($AV$6),ISNUMBER(AV14),AV14>$AV$6), AND(ISNUMBER($AW$6),ISNUMBER(AW14),AW14>$AW$6)),"Error", IF(SUM(AT14:AW14)>$AX$7,"Error", SUM(AT14:AW14)))))) | BC14: =IF(OR(F14="",COUNTA(AY14:BB14)=0),"", IF(COUNTA(AY14:BB14,$AY$6:$BB$6)=0,"", IF(OR( AND($AY$6="",AY14<>""),AND(ISTEXT($AY$6),$AY$6<>""),AND(ISTEXT(AY14),AY14<>""), AND($AZ$6="",AZ14<>""),AND(ISTEXT($AZ$6),$AZ$6<>""),AND(ISTEXT(AZ14),AZ14<>""), AND($BA$6="",BA14<>""),AND(ISTEXT($BA$6),$BA$6<>""),AND(ISTEXT(BA14),BA14<>""), AND($BB$6="",BB14<>""),AND(ISTEXT($BB$6),$BB$6<>""),AND(ISTEXT(BB14),BB14<>"")),"Error", IF(OR( AND(ISNUMBER($AY$6),ISNUMBER(AY14),AY14>$AY$6), AND(ISNUMBER($AZ$6),ISNUMBER(AZ14),AZ14>$AZ$6), AND(ISNUMBER($BA$6),ISNUMBER(BA14),BA14>$BA$6), AND(ISNUMBER($BB$6),ISNUMBER(BB14),BB14>$BB$6)),"Error", IF(SUM(AY14:BB14)>$BC$7,"Error", SUM(AY14:BB14)))))) | BE14: =IF(F14="","", IF(AND(BD14="",$BD$6=""),"", IF($BD$6="","Error", IF(OR(AND(ISTEXT(BD14),BD14<>""),AND(ISTEXT($BD$6),$BD$6<>"")),"Error", IF(AND(ISNUMBER(BD14),ISNUMBER($BD$6),BD14>$BD$6),"Error", IFERROR(IF(BD14="","",(BD14/$BD$6)*100),0))))))
